Workbook

Sheet 合计
A1: 2026年各平台边界利润汇总 (单位: CNY)
D2: 全年 | R2: 1月 | AG2: 2月 | AV2: 3月 | BK2: 4月 | BZ2: 5月 | CO2: 6月 | DD2: 7月 | DS2: 8月 | EH2: 9月 | EW2: 10月 | FL2: 11月 | GA2: 12月
D3: AMAZON | F3: TEMU | H3: SHEIN | J3: TK | L3: 综合部 | N3: 技术部 | P3: 合计 | R3: AMAZON | T3: TEMU | V3: SHEIN | X3: TK | Z3: 综合部 | AB3: 技术部 | AD3: 合计 | AF3: 环比 | AG3: AMAZON | AI3: TEMU | AK3: SHEIN | AM3: TK | AO3: 综合部 | AQ3: 技术部 | AS3: 合计 | AU3: 环比 | AV3: AMAZON | AX3: TEMU | AZ3: SHEIN | BB3: TK | BD3: 综合部 | BF3: 技术部 | BH3: 合计 | BJ3: 环比 | BK3: AMAZON | BM3: TEMU | BO3: SHEIN | BQ3: TK | BS3: 综合部 | BU3: 技术部 | BW3: 合计 | BY3: 环比 | BZ3: AMAZON | CB3: TEMU | CD3: SHEIN | CF3: TK | CH3: 综合部 | CJ3: 技术部 | CL3: 合计 | CN3: 环比 | CO3: AMAZON | CQ3: TEMU | CS3: SHEIN | CU3: TK | CW3: 综合部 | CY3: 技术部 | DA3: 合计 | DC3: 环比 | DD3: AMAZON | DF3: TEMU | DH3: SHEIN | DJ3: TK | DL3: 综合部 | DN3: 技术部 | DP3: 合计 | DR3: 环比 | DS3: AMAZON | DU3: TEMU | DW3: SHEIN | DY3: TK | EA3: 综合部 | EC3: 技术部 | EE3: 合计 | EG3: 环比 | EH3: AMAZON | EJ3: TEMU | EL3: SHEIN | EN3: TK | EP3: 综合部 | ER3: 技术部 | ET3: 合计 | EV3: 环比 | EW3: AMAZON | EY3: TEMU | FA3: SHEIN | FC3: TK | FE3: 综合部 | FG3: 技术部 | FI3: 合计 | FK3: 环比 | FL3: AMAZON | FN3: TEMU | FP3: SHEIN | FR3: TK | FT3: 综合部 | FV3: 技术部 | FX3: 合计 | FZ3: 环比 | GA3: AMAZON | GC3: TEMU | GE3: SHEIN | GG3: TK | GI3: 综合部 | GK3: 技术部 | GM3: 合计 | GO3: 环比
A4: 科目大类 | B4: 科目明细 | C4: 单位 | D4: 金额 | E4: 占比 | F4: 金额 | G4: 占比 | H4: 金额 | I4: 占比 | J4: 金额 | K4: 占比 | L4: 金额 | M4: 比例 | N4: 金额 | O4: 比例 | P4: 金额 | Q4: 比例 | R4: 合计 | S4: 占比 | T4: 合计 | U4: 占比 | V4: 合计 | W4: 占比 | X4: 合计 | Y4: 占比 | Z4: 金额 | AA4: 比例 | AB4: 金额 | AC4: 比例 | AD4: 金额 | AE4: 比例 | AF4: 环比 | AG4: 合计 | AH4: 占比 | AI4: 合计 | AJ4: 占比 | AK4: 合计 | AL4: 占比 | AM4: 合计 | AN4: 占比 | AO4: 金额 | AP4: 比例 | AQ4: 金额 | AR4: 比例 | AS4: 金额 | AT4: 比例 | AU4: 环比 | AV4: 合计 | AW4: 占比 | AX4: 合计 | AY4: 占比 | AZ4: 合计 | BA4: 占比 | BB4: 合计 | BC4: 占比 | BD4: 金额 | BE4: 比例 | BF4: 金额 | BG4: 比例 | BH4: 金额 | BI4: 比例 | BJ4: 环比 | BK4: 合计 | BL4: 占比 | BM4: 合计 | BN4: 占比 | BO4: 合计 | BP4: 占比 | BQ4: 合计 | BR4: 占比 | BS4: 金额 | BT4: 比例 | BU4: 金额 | BV4: 比例 | BW4: 金额 | BX4: 比例 | BY4: 环比 | BZ4: 合计 | CA4: 占比 | CB4: 合计 | CC4: 占比 | CD4: 合计 | CE4: 占比 | CF4: 合计 | CG4: 占比 | CH4: 金额 | CI4: 比例 | CJ4: 金额 | CK4: 比例 | CL4: 金额 | CM4: 比例 | CN4: 环比 | CO4: 合计 | CP4: 占比 | CQ4: 合计 | CR4: 占比 | CS4: 合计 | CT4: 占比 | CU4: 合计 | CV4: 占比 | CW4: 金额 | CX4: 比例 | CY4: 金额 | CZ4: 比例 | DA4: 金额 | DB4: 比例 | DC4: 环比 | DD4: 合计 | DE4: 占比 | DF4: 合计 | DG4: 占比 | DH4: 合计 | DI4: 占比 | DJ4: 合计 | DK4: 占比 | DL4: 金额 | DM4: 比例 | DN4: 金额 | DO4: 比例 | DP4: 金额 | DQ4: 比例 | DR4: 环比 | DS4: 合计 | DT4: 占比 | DU4: 合计 | DV4: 占比 | DW4: 合计 | DX4: 占比 | DY4: 合计 | DZ4: 占比 | EA4: 金额 | EB4: 比例 | EC4: 金额 | ED4: 比例 | EE4: 金额 | EF4: 比例 | EG4: 环比 | EH4: 合计 | EI4: 占比 | EJ4: 合计 | EK4: 占比 | EL4: 合计 | EM4: 占比 | EN4: 合计 | EO4: 占比 | EP4: 金额 | EQ4: 比例 | ER4: 金额 | ES4: 比例 | ET4: 金额 | EU4: 比例 | EV4: 环比 | EW4: 合计 | EX4: 占比 | EY4: 合计 | EZ4: 占比 | FA4: 合计 | FB4: 占比 | FC4: 合计 | FD4: 占比 | FE4: 金额 | FF4: 比例 | FG4: 金额 | FH4: 比例 | FI4: 金额 | FJ4: 比例 | FK4: 环比 | FL4: 合计 | FM4: 占比 | FN4: 合计 | FO4: 占比 | FP4: 合计 | FQ4: 占比 | FR4: 合计 | FS4: 占比 | FT4: 金额 | FU4: 比例 | FV4: 金额 | FW4: 比例 | FX4: 金额 | FY4: 比例 | FZ4: 环比 | GA4: 合计 | GB4: 占比 | GC4: 合计 | GD4: 占比 | GE4: 合计 | GF4: 占比 | GG4: 合计 | GH4: 占比 | GI4: 金额 | GJ4: 比例 | GK4: 金额 | GL4: 比例 | GM4: 金额 | GN4: 比例 | GO4: 环比
A5: 净销售量 | C5: 件 | D5: =AMAZON!F4 -> 0 | F5: =TEMU!F4 -> 0 | H5: =SHEIN!F4 -> 0 | J5: =TK!F4 -> 0 | P5: =D5+F5+H5+J5+L5+N5 -> 0 | Q5: =IFERROR(P5/(D11+F11+H11+J11),0) -> 0 | R5: =AMAZON!H4 -> 0 | T5: =TEMU!H4 -> 0 | V5: =SHEIN!H4 -> 0 | X5: =TK!H4 -> 0 | AD5: =R5+T5+V5+X5+Z5+AB5 -> 0 | AE5: =IFERROR(AD5/(R11+T11+V11+X11),0) -> 0 | AG5: =AMAZON!J4 -> 0 | AI5: =TEMU!J4 -> 0 | AK5: =SHEIN!J4 -> 0 | AM5: =TK!J4 -> 0 | AS5: =AG5+AI5+AK5+AM5+AO5+AQ5 -> 0 | AT5: =IFERROR(AS5/(AG11+AI11+AK11+AM11),0) -> 0 | AU5: =IFERROR((AS5-AD5)/AD5,0) -> 0 | AV5: =AMAZON!L4 -> 0 | AX5: =TEMU!L4 -> 0 | AZ5: =SHEIN!L4 -> 0 | BB5: =TK!L4 -> 0 | BH5: =AV5+AX5+AZ5+BB5+BD5+BF5 -> 0 | BI5: =IFERROR(BH5/(AV11+AX11+AZ11+BB11),0) -> 0 | BJ5: =IFERROR((BH5-AS5)/AS5,0) -> 0 | BK5: =AMAZON!N4 -> 0 | BM5: =TEMU!N4 -> 0 | BO5: =SHEIN!N4 -> 0 | BQ5: =TK!N4 -> 0 | BW5: =BK5+BM5+BO5+BQ5+BS5+BU5 -> 0 | BX5: =IFERROR(BW5/(BK11+BM11+BO11+BQ11),0) -> 0 | BY5: =IFERROR((BW5-BH5)/BH5,0) -> 0 | BZ5: =AMAZON!P4 -> 0 | CB5: =TEMU!P4 -> 0 | CD5: =SHEIN!P4 -> 0 | CF5: =TK!P4 -> 0 | CL5: =BZ5+CB5+CD5+CF5+CH5+CJ5 -> 0 | CM5: =IFERROR(CL5/(BZ11+CB11+CD11+CF11),0) -> 0 | CN5: =IFERROR((CL5-BW5)/BW5,0) -> 0 | CO5: =AMAZON!R4 -> 0 | CQ5: =TEMU!R4 -> 0 | CS5: =SHEIN!R4 -> 0 | CU5: =TK!R4 -> 0 | DA5: =CO5+CQ5+CS5+CU5+CW5+CY5 -> 0 | DB5: =IFERROR(DA5/(CO11+CQ11+CS11+CU11),0) -> 0 | DC5: =IFERROR((DA5-CL5)/CL5,0) -> 0 | DD5: =AMAZON!T4 -> 0 | DF5: =TEMU!T4 -> 0 | DH5: =SHEIN!T4 -> 0 | DJ5: =TK!T4 -> 0 | DP5: =DD5+DF5+DH5+DJ5+DL5+DN5 -> 0 | DQ5: =IFERROR(DP5/(DD11+DF11+DH11+DJ11),0) -> 0 | DR5: =IFERROR((DP5-DA5)/DA5,0) -> 0 | DS5: =AMAZON!V4 -> 0 | DU5: =TEMU!V4 -> 0 | DW5: =SHEIN!V4 -> 0 | DY5: =TK!V4 -> 0 | EE5: =DS5+DU5+DW5+DY5+EA5+EC5 -> 0 | EF5: =IFERROR(EE5/(DS11+DU11+DW11+DY11),0) -> 0 | EG5: =IFERROR((EE5-DP5)/DP5,0) -> 0 | EH5: =AMAZON!X4 -> 0 | EJ5: =TEMU!X4 -> 0 | EL5: =SHEIN!X4 -> 0 | EN5: =TK!X4 -> 0 | ET5: =EH5+EJ5+EL5+EN5+EP5+ER5 -> 0 | EU5: =IFERROR(ET5/(EH11+EJ11+EL11+EN11),0) -> 0 | EV5: =IFERROR((ET5-EE5)/EE5,0) -> 0 | EW5: =AMAZON!Z4 -> 0 | EY5: =TEMU!Z4 -> 0 | FA5: =SHEIN!Z4 -> 0 | FC5: =TK!Z4 -> 0 | FI5: =EW5+EY5+FA5+FC5+FE5+FG5 -> 0 | FJ5: =IFERROR(FI5/(EW11+EY11+FA11+FC11),0) -> 0 | FK5: =IFERROR((FI5-ET5)/ET5,0) -> 0 | FL5: =AMAZON!AB4 -> 0 | FN5: =TEMU!AB4 -> 0 | FP5: =SHEIN!AB4 -> 0 | FR5: =TK!AB4 -> 0 | FX5: =FL5+FN5+FP5+FR5+FT5+FV5 -> 0 | FY5: =IFERROR(FX5/(FL11+FN11+FP11+FR11),0) -> 0 | FZ5: =IFERROR((FX5-FI5)/FI5,0) -> 0 | GA5: =AMAZON!AD4 -> 0 | GC5: =TEMU!AD4 -> 0 | GE5: =SHEIN!AD4 -> 0 | GG5: =TK!AD4 -> 0 | GM5: =GA5+GC5+GE5+GG5+GI5+GK5 -> 0 | GN5: =IFERROR(GM5/(GA11+GC11+GE11+GG11),0) -> 0 | GO5: =IFERROR((GM5-FX5)/FX5,0) -> 0
A6: 净销售量 | B6: 销售量 | C6: 件 | D6: =AMAZON!F13 -> 0 | F6: =TEMU!F8 -> 0 | H6: =SHEIN!F7 -> 0 | J6: =TK!F8 -> 0 | P6: =D6+F6+H6+J6+L6+N6 -> 0 | Q6: =IFERROR(P6/(D11+F11+H11+J11),0) -> 0 | R6: =AMAZON!H13 -> 0 | T6: =TEMU!H8 -> 0 | V6: =SHEIN!H7 -> 0 | X6: =TK!H8 -> 0 | AD6: =R6+T6+V6+X6+Z6+AB6 -> 0 | AE6: =IFERROR(AD6/(R11+T11+V11+X11),0) -> 0 | AG6: =AMAZON!J13 -> 0 | AI6: =TEMU!J8 -> 0 | AK6: =SHEIN!J7 -> 0 | AM6: =TK!J8 -> 0 | AS6: =AG6+AI6+AK6+AM6+AO6+AQ6 -> 0 | AT6: =IFERROR(AS6/(AG11+AI11+AK11+AM11),0) -> 0 | AU6: =IFERROR((AS6-AD6)/AD6,0) -> 0 | AV6: =AMAZON!L13 -> 0 | AX6: =TEMU!L8 -> 0 | AZ6: =SHEIN!L7 -> 0 | BB6: =TK!L8 -> 0 | BH6: =AV6+AX6+AZ6+BB6+BD6+BF6 -> 0 | BI6: =IFERROR(BH6/(AV11+AX11+AZ11+BB11),0) -> 0 | BJ6: =IFERROR((BH6-AS6)/AS6,0) -> 0 | BK6: =AMAZON!N13 -> 0 | BM6: =TEMU!N8 -> 0 | BO6: =SHEIN!N7 -> 0 | BQ6: =TK!N8 -> 0 | BW6: =BK6+BM6+BO6+BQ6+BS6+BU6 -> 0 | BX6: =IFERROR(BW6/(BK11+BM11+BO11+BQ11),0) -> 0 | BY6: =IFERROR((BW6-BH6)/BH6,0) -> 0 | BZ6: =AMAZON!P13 -> 0 | CB6: =TEMU!P8 -> 0 | CD6: =SHEIN!P7 -> 0 | CF6: =TK!P8 -> 0 | CL6: =BZ6+CB6+CD6+CF6+CH6+CJ6 -> 0 | CM6: =IFERROR(CL6/(BZ11+CB11+CD11+CF11),0) -> 0 | CN6: =IFERROR((CL6-BW6)/BW6,0) -> 0 | CO6: =AMAZON!R13 -> 0 | CQ6: =TEMU!R8 -> 0 | CS6: =SHEIN!R7 -> 0 | CU6: =TK!R8 -> 0 | DA6: =CO6+CQ6+CS6+CU6+CW6+CY6 -> 0 | DB6: =IFERROR(DA6/(CO11+CQ11+CS11+CU11),0) -> 0 | DC6: =IFERROR((DA6-CL6)/CL6,0) -> 0 | DD6: =AMAZON!T13 -> 0 | DF6: =TEMU!T8 -> 0 | DH6: =SHEIN!T7 -> 0 | DJ6: =TK!T8 -> 0 | DP6: =DD6+DF6+DH6+DJ6+DL6+DN6 -> 0 | DQ6: =IFERROR(DP6/(DD11+DF11+DH11+DJ11),0) -> 0 | DR6: =IFERROR((DP6-DA6)/DA6,0) -> 0 | DS6: =AMAZON!V13 -> 0 | DU6: =TEMU!V8 -> 0 | DW6: =SHEIN!V7 -> 0 | DY6: =TK!V8 -> 0 | EE6: =DS6+DU6+DW6+DY6+EA6+EC6 -> 0 | EF6: =IFERROR(EE6/(DS11+DU11+DW11+DY11),0) -> 0 | EG6: =IFERROR((EE6-DP6)/DP6,0) -> 0 | EH6: =AMAZON!X13 -> 0 | EJ6: =TEMU!X8 -> 0 | EL6: =SHEIN!X7 -> 0 | EN6: =TK!X8 -> 0 | ET6: =EH6+EJ6+EL6+EN6+EP6+ER6 -> 0 | EU6: =IFERROR(ET6/(EH11+EJ11+EL11+EN11),0) -> 0 | EV6: =IFERROR((ET6-EE6)/EE6,0) -> 0 | EW6: =AMAZON!Z13 -> 0 | EY6: =TEMU!Z8 -> 0 | FA6: =SHEIN!Z7 -> 0 | FC6: =TK!Z8 -> 0 | FI6: =EW6+EY6+FA6+FC6+FE6+FG6 -> 0 | FJ6: =IFERROR(FI6/(EW11+EY11+FA11+FC11),0) -> 0 | FK6: =IFERROR((FI6-ET6)/ET6,0) -> 0 | FL6: =AMAZON!AB13 -> 0 | FN6: =TEMU!AB8 -> 0 | FP6: =SHEIN!AB7 -> 0 | FR6: =TK!AB8 -> 0 | FX6: =FL6+FN6+FP6+FR6+FT6+FV6 -> 0 | FY6: =IFERROR(FX6/(FL11+FN11+FP11+FR11),0) -> 0 | FZ6: =IFERROR((FX6-FI6)/FI6,0) -> 0 | GA6: =AMAZON!AD13 -> 0 | GC6: =TEMU!AD8 -> 0 | GE6: =SHEIN!AD7 -> 0 | GG6: =TK!AD8 -> 0 | GM6: =GA6+GC6+GE6+GG6+GI6+GK6 -> 0 | GN6: =IFERROR(GM6/(GA11+GC11+GE11+GG11),0) -> 0 | GO6: =IFERROR((GM6-FX6)/FX6,0) -> 0
A7: 净销售量 | B7: 退款量 | C7: 件 | D7: =AMAZON!F22 -> 0 | F7: =TEMU!F12 -> 0 | H7: =SHEIN!F10 -> 0 | J7: =TK!F12 -> 0 | P7: =D7+F7+H7+J7+L7+N7 -> 0 | Q7: =IFERROR(P7/(D11+F11+H11+J11),0) -> 0 | R7: =AMAZON!H22 -> 0 | T7: =TEMU!H12 -> 0 | V7: =SHEIN!H10 -> 0 | X7: =TK!H12 -> 0 | AD7: =R7+T7+V7+X7+Z7+AB7 -> 0 | AE7: =IFERROR(AD7/(R11+T11+V11+X11),0) -> 0 | AG7: =AMAZON!J22 -> 0 | AI7: =TEMU!J12 -> 0 | AK7: =SHEIN!J10 -> 0 | AM7: =TK!J12 -> 0 | AS7: =AG7+AI7+AK7+AM7+AO7+AQ7 -> 0 | AT7: =IFERROR(AS7/(AG11+AI11+AK11+AM11),0) -> 0 | AU7: =IFERROR((AS7-AD7)/AD7,0) -> 0 | AV7: =AMAZON!L22 -> 0 | AX7: =TEMU!L12 -> 0 | AZ7: =SHEIN!L10 -> 0 | BB7: =TK!L12 -> 0 | BH7: =AV7+AX7+AZ7+BB7+BD7+BF7 -> 0 | BI7: =IFERROR(BH7/(AV11+AX11+AZ11+BB11),0) -> 0 | BJ7: =IFERROR((BH7-AS7)/AS7,0) -> 0 | BK7: =AMAZON!N22 -> 0 | BM7: =TEMU!N12 -> 0 | BO7: =SHEIN!N10 -> 0 | BQ7: =TK!N12 -> 0 | BW7: =BK7+BM7+BO7+BQ7+BS7+BU7 -> 0 | BX7: =IFERROR(BW7/(BK11+BM11+BO11+BQ11),0) -> 0 | BY7: =IFERROR((BW7-BH7)/BH7,0) -> 0 | BZ7: =AMAZON!P22 -> 0 | CB7: =TEMU!P12 -> 0 | CD7: =SHEIN!P10 -> 0 | CF7: =TK!P12 -> 0 | CL7: =BZ7+CB7+CD7+CF7+CH7+CJ7 -> 0 | CM7: =IFERROR(CL7/(BZ11+CB11+CD11+CF11),0) -> 0 | CN7: =IFERROR((CL7-BW7)/BW7,0) -> 0 | CO7: =AMAZON!R22 -> 0 | CQ7: =TEMU!R12 -> 0 | CS7: =SHEIN!R10 -> 0 | CU7: =TK!R12 -> 0 | DA7: =CO7+CQ7+CS7+CU7+CW7+CY7 -> 0 | DB7: =IFERROR(DA7/(CO11+CQ11+CS11+CU11),0) -> 0 | DC7: =IFERROR((DA7-CL7)/CL7,0) -> 0 | DD7: =AMAZON!T22 -> 0 | DF7: =TEMU!T12 -> 0 | DH7: =SHEIN!T10 -> 0 | DJ7: =TK!T12 -> 0 | DP7: =DD7+DF7+DH7+DJ7+DL7+DN7 -> 0 | DQ7: =IFERROR(DP7/(DD11+DF11+DH11+DJ11),0) -> 0 | DR7: =IFERROR((DP7-DA7)/DA7,0) -> 0 | DS7: =AMAZON!V22 -> 0 | DU7: =TEMU!V12 -> 0 | DW7: =SHEIN!V10 -> 0 | DY7: =TK!V12 -> 0 | EE7: =DS7+DU7+DW7+DY7+EA7+EC7 -> 0 | EF7: =IFERROR(EE7/(DS11+DU11+DW11+DY11),0) -> 0 | EG7: =IFERROR((EE7-DP7)/DP7,0) -> 0 | EH7: =AMAZON!X22 -> 0 | EJ7: =TEMU!X12 -> 0 | EL7: =SHEIN!X10 -> 0 | EN7: =TK!X12 -> 0 | ET7: =EH7+EJ7+EL7+EN7+EP7+ER7 -> 0 | EU7: =IFERROR(ET7/(EH11+EJ11+EL11+EN11),0) -> 0 | EV7: =IFERROR((ET7-EE7)/EE7,0) -> 0 | EW7: =AMAZON!Z22 -> 0 | EY7: =TEMU!Z12 -> 0 | FA7: =SHEIN!Z10 -> 0 | FC7: =TK!Z12 -> 0 | FI7: =EW7+EY7+FA7+FC7+FE7+FG7 -> 0 | FJ7: =IFERROR(FI7/(EW11+EY11+FA11+FC11),0) -> 0 | FK7: =IFERROR((FI7-ET7)/ET7,0) -> 0 | FL7: =AMAZON!AB22 -> 0 | FN7: =TEMU!AB12 -> 0 | FP7: =SHEIN!AB10 -> 0 | FR7: =TK!AB12 -> 0 | FX7: =FL7+FN7+FP7+FR7+FT7+FV7 -> 0 | FY7: =IFERROR(FX7/(FL11+FN11+FP11+FR11),0) -> 0 | FZ7: =IFERROR((FX7-FI7)/FI7,0) -> 0 | GA7: =AMAZON!AD22 -> 0 | GC7: =TEMU!AD12 -> 0 | GE7: =SHEIN!AD10 -> 0 | GG7: =TK!AD12 -> 0 | GM7: =GA7+GC7+GE7+GG7+GI7+GK7 -> 0 | GN7: =IFERROR(GM7/(GA11+GC11+GE11+GG11),0) -> 0 | GO7: =IFERROR((GM7-FX7)/FX7,0) -> 0
A8: 毛利率 | C8: % | D8: =IFERROR(AMAZON!F31,"") -> 0 | F8: =IFERROR(TEMU!F16,"") -> 0 | H8: =IFERROR(SHEIN!F13,"") -> 0 | J8: =IFERROR(TK!F16,"") -> 0 | P8: =D8+F8+H8+J8+L8+N8 -> 0 | Q8: =IFERROR(P8/(D11+F11+H11+J11),0) -> 0 | R8: =IFERROR(AMAZON!H31,"") | T8: =IFERROR(TEMU!H16,"") | V8: =IFERROR(SHEIN!H13,"") | X8: =IFERROR(TK!H16,"") | AD8: =R8+T8+V8+X8+Z8+AB8 -> #VALUE! | AE8: =IFERROR(AD8/(R11+T11+V11+X11),0) -> 0 | AG8: =IFERROR(AMAZON!J31,"") | AI8: =IFERROR(TEMU!J16,"") | AK8: =IFERROR(SHEIN!J13,"") | AM8: =IFERROR(TK!J16,"") | AS8: =AG8+AI8+AK8+AM8+AO8+AQ8 -> #VALUE! | AT8: =IFERROR(AS8/(AG11+AI11+AK11+AM11),0) -> 0 | AU8: =IFERROR((AS8-AD8)/AD8,0) -> 0 | AV8: =IFERROR(AMAZON!L31,"") | AX8: =IFERROR(TEMU!L16,"") | AZ8: =IFERROR(SHEIN!L13,"") | BB8: =IFERROR(TK!L16,"") | BH8: =AV8+AX8+AZ8+BB8+BD8+BF8 -> #VALUE! | BI8: =IFERROR(BH8/(AV11+AX11+AZ11+BB11),0) -> 0 | BJ8: =IFERROR((BH8-AS8)/AS8,0) -> 0 | BK8: =IFERROR(AMAZON!N31,"") | BM8: =IFERROR(TEMU!N16,"") | BO8: =IFERROR(SHEIN!N13,"") | BQ8: =IFERROR(TK!N16,"") | BW8: =BK8+BM8+BO8+BQ8+BS8+BU8 -> #VALUE! | BX8: =IFERROR(BW8/(BK11+BM11+BO11+BQ11),0) -> 0 | BY8: =IFERROR((BW8-BH8)/BH8,0) -> 0 | BZ8: =IFERROR(AMAZON!P31,"") | CB8: =IFERROR(TEMU!P16,"") | CD8: =IFERROR(SHEIN!P13,"") | CF8: =IFERROR(TK!P16,"") | CL8: =BZ8+CB8+CD8+CF8+CH8+CJ8 -> #VALUE! | CM8: =IFERROR(CL8/(BZ11+CB11+CD11+CF11),0) -> 0 | CN8: =IFERROR((CL8-BW8)/BW8,0) -> 0 | CO8: =IFERROR(AMAZON!R31,"") | CQ8: =IFERROR(TEMU!R16,"") | CS8: =IFERROR(SHEIN!R13,"") | CU8: =IFERROR(TK!R16,"") | DA8: =CO8+CQ8+CS8+CU8+CW8+CY8 -> #VALUE! | DB8: =IFERROR(DA8/(CO11+CQ11+CS11+CU11),0) -> 0 | DC8: =IFERROR((DA8-CL8)/CL8,0) -> 0 | DD8: =IFERROR(AMAZON!T31,"") | DF8: =IFERROR(TEMU!T16,"") | DH8: =IFERROR(SHEIN!T13,"") | DJ8: =IFERROR(TK!T16,"") | DP8: =DD8+DF8+DH8+DJ8+DL8+DN8 -> #VALUE! | DQ8: =IFERROR(DP8/(DD11+DF11+DH11+DJ11),0) -> 0 | DR8: =IFERROR((DP8-DA8)/DA8,0) -> 0 | DS8: =IFERROR(AMAZON!V31,"") | DU8: =IFERROR(TEMU!V16,"") | DW8: =IFERROR(SHEIN!V13,"") | DY8: =IFERROR(TK!V16,"") | EE8: =DS8+DU8+DW8+DY8+EA8+EC8 -> #VALUE! | EF8: =IFERROR(EE8/(DS11+DU11+DW11+DY11),0) -> 0 | EG8: =IFERROR((EE8-DP8)/DP8,0) -> 0 | EH8: =IFERROR(AMAZON!X31,"") | EJ8: =IFERROR(TEMU!X16,"") | EL8: =IFERROR(SHEIN!X13,"") | EN8: =IFERROR(TK!X16,"") | ET8: =EH8+EJ8+EL8+EN8+EP8+ER8 -> #VALUE! | EU8: =IFERROR(ET8/(EH11+EJ11+EL11+EN11),0) -> 0 | EV8: =IFERROR((ET8-EE8)/EE8,0) -> 0 | EW8: =IFERROR(AMAZON!Z31,"") | EY8: =IFERROR(TEMU!Z16,"") | FA8: =IFERROR(SHEIN!Z13,"") | FC8: =IFERROR(TK!Z16,"") | FI8: =EW8+EY8+FA8+FC8+FE8+FG8 -> #VALUE! | FJ8: =IFERROR(FI8/(EW11+EY11+FA11+FC11),0) -> 0 | FK8: =IFERROR((FI8-ET8)/ET8,0) -> 0 | FL8: =IFERROR(AMAZON!AB31,"") | FN8: =IFERROR(TEMU!AB16,"") | FP8: =IFERROR(SHEIN!AB13,"") | FR8: =IFERROR(TK!AB16,"") | FX8: =FL8+FN8+FP8+FR8+FT8+FV8 -> #VALUE! | FY8: =IFERROR(FX8/(FL11+FN11+FP11+FR11),0) -> 0 | FZ8: =IFERROR((FX8-FI8)/FI8,0) -> 0 | GA8: =IFERROR(AMAZON!AD31,"") | GC8: =IFERROR(TEMU!AD16,"") | GE8: =IFERROR(SHEIN!AD13,"") | GG8: =IFERROR(TK!AD16,"") | GM8: =GA8+GC8+GE8+GG8+GI8+GK8 -> #VALUE! | GN8: =IFERROR(GM8/(GA11+GC11+GE11+GG11),0) -> 0 | GO8: =IFERROR((GM8-FX8)/FX8,0) -> 0
A9: 经营收入 | C9: 元 | D9: =AMAZON!F40 -> 0 | E9: =IFERROR(D9/AMAZON!F50,0) -> 0 | F9: =TEMU!F20 -> 0 | G9: =IFERROR(F9/TEMU!F25,0) -> 0 | H9: =SHEIN!F16 -> 0 | I9: =IFERROR(H9/SHEIN!F20,0) -> 0 | J9: =TK!F20 -> 0 | K9: =IFERROR(J9/TK!F25,0) -> 0 | P9: =D9+F9+H9+J9+L9+N9 -> 0 | Q9: =IFERROR(P9/(D11+F11+H11+J11),0) -> 0 | R9: =AMAZON!H40 -> 0 | S9: =IFERROR(R9/AMAZON!H50,0) -> 0 | T9: =TEMU!H20 -> 0 | U9: =IFERROR(T9/TEMU!H25,0) -> 0 | V9: =SHEIN!H16 -> 0 | W9: =IFERROR(V9/SHEIN!H20,0) -> 0 | X9: =TK!H20 -> 0 | Y9: =IFERROR(X9/TK!H25,0) -> 0 | AD9: =R9+T9+V9+X9+Z9+AB9 -> 0 | AE9: =IFERROR(AD9/(R11+T11+V11+X11),0) -> 0 | AG9: =AMAZON!J40 -> 0 | AH9: =IFERROR(AG9/AMAZON!J50,0) -> 0 | AI9: =TEMU!J20 -> 0 | AJ9: =IFERROR(AI9/TEMU!J25,0) -> 0 | AK9: =SHEIN!J16 -> 0 | AL9: =IFERROR(AK9/SHEIN!J20,0) -> 0 | AM9: =TK!J20 -> 0 | AN9: =IFERROR(AM9/TK!J25,0) -> 0 | AS9: =AG9+AI9+AK9+AM9+AO9+AQ9 -> 0 | AT9: =IFERROR(AS9/(AG11+AI11+AK11+AM11),0) -> 0 | AU9: =IFERROR((AS9-AD9)/AD9,0) -> 0 | AV9: =AMAZON!L40 -> 0 | AW9: =IFERROR(AV9/AMAZON!L50,0) -> 0 | AX9: =TEMU!L20 -> 0 | AY9: =IFERROR(AX9/TEMU!L25,0) -> 0 | AZ9: =SHEIN!L16 -> 0 | BA9: =IFERROR(AZ9/SHEIN!L20,0) -> 0 | BB9: =TK!L20 -> 0 | BC9: =IFERROR(BB9/TK!L25,0) -> 0 | BH9: =AV9+AX9+AZ9+BB9+BD9+BF9 -> 0 | BI9: =IFERROR(BH9/(AV11+AX11+AZ11+BB11),0) -> 0 | BJ9: =IFERROR((BH9-AS9)/AS9,0) -> 0 | BK9: =AMAZON!N40 -> 0 | BL9: =IFERROR(BK9/AMAZON!N50,0) -> 0 | BM9: =TEMU!N20 -> 0 | BN9: =IFERROR(BM9/TEMU!N25,0) -> 0 | BO9: =SHEIN!N16 -> 0 | BP9: =IFERROR(BO9/SHEIN!N20,0) -> 0 | BQ9: =TK!N20 -> 0 | BR9: =IFERROR(BQ9/TK!N25,0) -> 0 | BW9: =BK9+BM9+BO9+BQ9+BS9+BU9 -> 0 | BX9: =IFERROR(BW9/(BK11+BM11+BO11+BQ11),0) -> 0 | BY9: =IFERROR((BW9-BH9)/BH9,0) -> 0 | BZ9: =AMAZON!P40 -> 0 | CA9: =IFERROR(BZ9/AMAZON!P50,0) -> 0 | CB9: =TEMU!P20 -> 0 | CC9: =IFERROR(CB9/TEMU!P25,0) -> 0 | CD9: =SHEIN!P16 -> 0 | CE9: =IFERROR(CD9/SHEIN!P20,0) -> 0 | CF9: =TK!P20 -> 0 | CG9: =IFERROR(CF9/TK!P25,0) -> 0 | CL9: =BZ9+CB9+CD9+CF9+CH9+CJ9 -> 0 | CM9: =IFERROR(CL9/(BZ11+CB11+CD11+CF11),0) -> 0 | CN9: =IFERROR((CL9-BW9)/BW9,0) -> 0 | CO9: =AMAZON!R40 -> 0 | CP9: =IFERROR(CO9/AMAZON!R50,0) -> 0 | CQ9: =TEMU!R20 -> 0 | CR9: =IFERROR(CQ9/TEMU!R25,0) -> 0 | CS9: =SHEIN!R16 -> 0 | CT9: =IFERROR(CS9/SHEIN!R20,0) -> 0 | CU9: =TK!R20 -> 0 | CV9: =IFERROR(CU9/TK!R25,0) -> 0 | DA9: =CO9+CQ9+CS9+CU9+CW9+CY9 -> 0 | DB9: =IFERROR(DA9/(CO11+CQ11+CS11+CU11),0) -> 0 | DC9: =IFERROR((DA9-CL9)/CL9,0) -> 0 | DD9: =AMAZON!T40 -> 0 | DE9: =IFERROR(DD9/AMAZON!T50,0) -> 0 | DF9: =TEMU!T20 -> 0 | DG9: =IFERROR(DF9/TEMU!T25,0) -> 0 | DH9: =SHEIN!T16 -> 0 | DI9: =IFERROR(DH9/SHEIN!T20,0) -> 0 | DJ9: =TK!T20 -> 0 | DK9: =IFERROR(DJ9/TK!T25,0) -> 0 | DP9: =DD9+DF9+DH9+DJ9+DL9+DN9 -> 0 | DQ9: =IFERROR(DP9/(DD11+DF11+DH11+DJ11),0) -> 0 | DR9: =IFERROR((DP9-DA9)/DA9,0) -> 0 | DS9: =AMAZON!V40 -> 0 | DT9: =IFERROR(DS9/AMAZON!V50,0) -> 0 | DU9: =TEMU!V20 -> 0 | DV9: =IFERROR(DU9/TEMU!V25,0) -> 0 | DW9: =SHEIN!V16 -> 0 | DX9: =IFERROR(DW9/SHEIN!V20,0) -> 0 | DY9: =TK!V20 -> 0 | DZ9: =IFERROR(DY9/TK!V25,0) -> 0 | EE9: =DS9+DU9+DW9+DY9+EA9+EC9 -> 0 | EF9: =IFERROR(EE9/(DS11+DU11+DW11+DY11),0) -> 0 | EG9: =IFERROR((EE9-DP9)/DP9,0) -> 0 | EH9: =AMAZON!X40 -> 0 | EI9: =IFERROR(EH9/AMAZON!X50,0) -> 0 | EJ9: =TEMU!X20 -> 0 | EK9: =IFERROR(EJ9/TEMU!X25,0) -> 0 | EL9: =SHEIN!X16 -> 0 | EM9: =IFERROR(EL9/SHEIN!X20,0) -> 0 | EN9: =TK!X20 -> 0 | EO9: =IFERROR(EN9/TK!X25,0) -> 0 | ET9: =EH9+EJ9+EL9+EN9+EP9+ER9 -> 0 | EU9: =IFERROR(ET9/(EH11+EJ11+EL11+EN11),0) -> 0 | EV9: =IFERROR((ET9-EE9)/EE9,0) -> 0 | EW9: =AMAZON!Z40 -> 0 | EX9: =IFERROR(EW9/AMAZON!Z50,0) -> 0 | EY9: =TEMU!Z20 -> 0 | EZ9: =IFERROR(EY9/TEMU!Z25,0) -> 0 | FA9: =SHEIN!Z16 -> 0 | FB9: =IFERROR(FA9/SHEIN!Z20,0) -> 0 | FC9: =TK!Z20 -> 0 | FD9: =IFERROR(FC9/TK!Z25,0) -> 0 | FI9: =EW9+EY9+FA9+FC9+FE9+FG9 -> 0 | FJ9: =IFERROR(FI9/(EW11+EY11+FA11+FC11),0) -> 0 | FK9: =IFERROR((FI9-ET9)/ET9,0) -> 0 | FL9: =AMAZON!AB40 -> 0 | FM9: =IFERROR(FL9/AMAZON!AB50,0) -> 0 | FN9: =TEMU!AB20 -> 0 | FO9: =IFERROR(FN9/TEMU!AB25,0) -> 0 | FP9: =SHEIN!AB16 -> 0 | FQ9: =IFERROR(FP9/SHEIN!AB20,0) -> 0 | FR9: =TK!AB20 -> 0 | FS9: =IFERROR(FR9/TK!AB25,0) -> 0 | FX9: =FL9+FN9+FP9+FR9+FT9+FV9 -> 0 | FY9: =IFERROR(FX9/(FL11+FN11+FP11+FR11),0) -> 0 | FZ9: =IFERROR((FX9-FI9)/FI9,0) -> 0 | GA9: =AMAZON!AD40 -> 0 | GB9: =IFERROR(GA9/AMAZON!AD50,0) -> 0 | GC9: =TEMU!AD20 -> 0 | GD9: =IFERROR(GC9/TEMU!AD25,0) -> 0 | GE9: =SHEIN!AD16 -> 0 | GF9: =IFERROR(GE9/SHEIN!AD20,0) -> 0 | GG9: =TK!AD20 -> 0 | GH9: =IFERROR(GG9/TK!AD25,0) -> 0 | GM9: =GA9+GC9+GE9+GG9+GI9+GK9 -> 0 | GN9: =IFERROR(GM9/(GA11+GC11+GE11+GG11),0) -> 0 | GO9: =IFERROR((GM9-FX9)/FX9,0) -> 0
A10: 经营销售 | C10: 元 | D10: =AMAZON!F41 -> 0 | E10: =IFERROR(D10/AMAZON!F50,0) -> 0 | F10: =TEMU!F21 -> 0 | G10: =IFERROR(F10/TEMU!F25,0) -> 0 | H10: =SHEIN!F17 -> 0 | I10: =IFERROR(H10/SHEIN!F20,0) -> 0 | J10: =TK!F21 -> 0 | K10: =IFERROR(J10/TK!F25,0) -> 0 | P10: =D10+F10+H10+J10+L10+N10 -> 0 | Q10: =IFERROR(P10/(D11+F11+H11+J11),0) -> 0 | R10: =AMAZON!H41 -> 0 | S10: =IFERROR(R10/AMAZON!H50,0) -> 0 | T10: =TEMU!H21 -> 0 | U10: =IFERROR(T10/TEMU!H25,0) -> 0 | V10: =SHEIN!H17 -> 0 | W10: =IFERROR(V10/SHEIN!H20,0) -> 0 | X10: =TK!H21 -> 0 | Y10: =IFERROR(X10/TK!H25,0) -> 0 | AD10: =R10+T10+V10+X10+Z10+AB10 -> 0 | AE10: =IFERROR(AD10/(R11+T11+V11+X11),0) -> 0 | AG10: =AMAZON!J41 -> 0 | AH10: =IFERROR(AG10/AMAZON!J50,0) -> 0 | AI10: =TEMU!J21 -> 0 | AJ10: =IFERROR(AI10/TEMU!J25,0) -> 0 | AK10: =SHEIN!J17 -> 0 | AL10: =IFERROR(AK10/SHEIN!J20,0) -> 0 | AM10: =TK!J21 -> 0 | AN10: =IFERROR(AM10/TK!J25,0) -> 0 | AS10: =AG10+AI10+AK10+AM10+AO10+AQ10 -> 0 | AT10: =IFERROR(AS10/(AG11+AI11+AK11+AM11),0) -> 0 | AU10: =IFERROR((AS10-AD10)/AD10,0) -> 0 | AV10: =AMAZON!L41 -> 0 | AW10: =IFERROR(AV10/AMAZON!L50,0) -> 0 | AX10: =TEMU!L21 -> 0 | AY10: =IFERROR(AX10/TEMU!L25,0) -> 0 | AZ10: =SHEIN!L17 -> 0 | BA10: =IFERROR(AZ10/SHEIN!L20,0) -> 0 | BB10: =TK!L21 -> 0 | BC10: =IFERROR(BB10/TK!L25,0) -> 0 | BH10: =AV10+AX10+AZ10+BB10+BD10+BF10 -> 0 | BI10: =IFERROR(BH10/(AV11+AX11+AZ11+BB11),0) -> 0 | BJ10: =IFERROR((BH10-AS10)/AS10,0) -> 0 | BK10: =AMAZON!N41 -> 0 | BL10: =IFERROR(BK10/AMAZON!N50,0) -> 0 | BM10: =TEMU!N21 -> 0 | BN10: =IFERROR(BM10/TEMU!N25,0) -> 0 | BO10: =SHEIN!N17 -> 0 | BP10: =IFERROR(BO10/SHEIN!N20,0) -> 0 | BQ10: =TK!N21 -> 0 | BR10: =IFERROR(BQ10/TK!N25,0) -> 0 | BW10: =BK10+BM10+BO10+BQ10+BS10+BU10 -> 0 | BX10: =IFERROR(BW10/(BK11+BM11+BO11+BQ11),0) -> 0 | BY10: =IFERROR((BW10-BH10)/BH10,0) -> 0 | BZ10: =AMAZON!P41 -> 0 | CA10: =IFERROR(BZ10/AMAZON!P50,0) -> 0 | CB10: =TEMU!P21 -> 0 | CC10: =IFERROR(CB10/TEMU!P25,0) -> 0 | CD10: =SHEIN!P17 -> 0 | CE10: =IFERROR(CD10/SHEIN!P20,0) -> 0 | CF10: =TK!P21 -> 0 | CG10: =IFERROR(CF10/TK!P25,0) -> 0 | CL10: =BZ10+CB10+CD10+CF10+CH10+CJ10 -> 0 | CM10: =IFERROR(CL10/(BZ11+CB11+CD11+CF11),0) -> 0 | CN10: =IFERROR((CL10-BW10)/BW10,0) -> 0 | CO10: =AMAZON!R41 -> 0 | CP10: =IFERROR(CO10/AMAZON!R50,0) -> 0 | CQ10: =TEMU!R21 -> 0 | CR10: =IFERROR(CQ10/TEMU!R25,0) -> 0 | CS10: =SHEIN!R17 -> 0 | CT10: =IFERROR(CS10/SHEIN!R20,0) -> 0 | CU10: =TK!R21 -> 0 | CV10: =IFERROR(CU10/TK!R25,0) -> 0 | DA10: =CO10+CQ10+CS10+CU10+CW10+CY10 -> 0 | DB10: =IFERROR(DA10/(CO11+CQ11+CS11+CU11),0) -> 0 | DC10: =IFERROR((DA10-CL10)/CL10,0) -> 0 | DD10: =AMAZON!T41 -> 0 | DE10: =IFERROR(DD10/AMAZON!T50,0) -> 0 | DF10: =TEMU!T21 -> 0 | DG10: =IFERROR(DF10/TEMU!T25,0) -> 0 | DH10: =SHEIN!T17 -> 0 | DI10: =IFERROR(DH10/SHEIN!T20,0) -> 0 | DJ10: =TK!T21 -> 0 | DK10: =IFERROR(DJ10/TK!T25,0) -> 0 | DP10: =DD10+DF10+DH10+DJ10+DL10+DN10 -> 0 | DQ10: =IFERROR(DP10/(DD11+DF11+DH11+DJ11),0) -> 0 | DR10: =IFERROR((DP10-DA10)/DA10,0) -> 0 | DS10: =AMAZON!V41 -> 0 | DT10: =IFERROR(DS10/AMAZON!V50,0) -> 0 | DU10: =TEMU!V21 -> 0 | DV10: =IFERROR(DU10/TEMU!V25,0) -> 0 | DW10: =SHEIN!V17 -> 0 | DX10: =IFERROR(DW10/SHEIN!V20,0) -> 0 | DY10: =TK!V21 -> 0 | DZ10: =IFERROR(DY10/TK!V25,0) -> 0 | EE10: =DS10+DU10+DW10+DY10+EA10+EC10 -> 0 | EF10: =IFERROR(EE10/(DS11+DU11+DW11+DY11),0) -> 0 | EG10: =IFERROR((EE10-DP10)/DP10,0) -> 0 | EH10: =AMAZON!X41 -> 0 | EI10: =IFERROR(EH10/AMAZON!X50,0) -> 0 | EJ10: =TEMU!X21 -> 0 | EK10: =IFERROR(EJ10/TEMU!X25,0) -> 0 | EL10: =SHEIN!X17 -> 0 | EM10: =IFERROR(EL10/SHEIN!X20,0) -> 0 | EN10: =TK!X21 -> 0 | EO10: =IFERROR(EN10/TK!X25,0) -> 0 | ET10: =EH10+EJ10+EL10+EN10+EP10+ER10 -> 0 | EU10: =IFERROR(ET10/(EH11+EJ11+EL11+EN11),0) -> 0 | EV10: =IFERROR((ET10-EE10)/EE10,0) -> 0 | EW10: =AMAZON!Z41 -> 0 | EX10: =IFERROR(EW10/AMAZON!Z50,0) -> 0 | EY10: =TEMU!Z21 -> 0 | EZ10: =IFERROR(EY10/TEMU!Z25,0) -> 0 | FA10: =SHEIN!Z17 -> 0 | FB10: =IFERROR(FA10/SHEIN!Z20,0) -> 0 | FC10: =TK!Z21 -> 0 | FD10: =IFERROR(FC10/TK!Z25,0) -> 0 | FI10: =EW10+EY10+FA10+FC10+FE10+FG10 -> 0 | FJ10: =IFERROR(FI10/(EW11+EY11+FA11+FC11),0) -> 0 | FK10: =IFERROR((FI10-ET10)/ET10,0) -> 0 | FL10: =AMAZON!AB41 -> 0 | FM10: =IFERROR(FL10/AMAZON!AB50,0) -> 0 | FN10: =TEMU!AB21 -> 0 | FO10: =IFERROR(FN10/TEMU!AB25,0) -> 0 | FP10: =SHEIN!AB17 -> 0 | FQ10: =IFERROR(FP10/SHEIN!AB20,0) -> 0 | FR10: =TK!AB21 -> 0 | FS10: =IFERROR(FR10/TK!AB25,0) -> 0 | FX10: =FL10+FN10+FP10+FR10+FT10+FV10 -> 0 | FY10: =IFERROR(FX10/(FL11+FN11+FP11+FR11),0) -> 0 | FZ10: =IFERROR((FX10-FI10)/FI10,0) -> 0 | GA10: =AMAZON!AD41 -> 0 | GB10: =IFERROR(GA10/AMAZON!AD50,0) -> 0 | GC10: =TEMU!AD21 -> 0 | GD10: =IFERROR(GC10/TEMU!AD25,0) -> 0 | GE10: =SHEIN!AD17 -> 0 | GF10: =IFERROR(GE10/SHEIN!AD20,0) -> 0 | GG10: =TK!AD21 -> 0 | GH10: =IFERROR(GG10/TK!AD25,0) -> 0 | GM10: =GA10+GC10+GE10+GG10+GI10+GK10 -> 0 | GN10: =IFERROR(GM10/(GA11+GC11+GE11+GG11),0) -> 0 | GO10: =IFERROR((GM10-FX10)/FX10,0) -> 0
A11: 经营销售 | B11: 销售额 | C11: 元 | D11: =AMAZON!F50 -> 0 | E11: =IFERROR(D11/AMAZON!F50,0) -> 0 | F11: =TEMU!F25 -> 0 | G11: =IFERROR(F11/TEMU!F25,0) -> 0 | H11: =SHEIN!F20 -> 0 | I11: =IFERROR(H11/SHEIN!F20,0) -> 0 | J11: =TK!F25 -> 0 | K11: =IFERROR(J11/TK!F25,0) -> 0 | P11: =D11+F11+H11+J11+L11+N11 -> 0 | Q11: =IFERROR(P11/(D11+F11+H11+J11),0) -> 0 | R11: =AMAZON!H50 -> 0 | S11: =IFERROR(R11/AMAZON!H50,0) -> 0 | T11: =TEMU!H25 -> 0 | U11: =IFERROR(T11/TEMU!H25,0) -> 0 | V11: =SHEIN!H20 -> 0 | W11: =IFERROR(V11/SHEIN!H20,0) -> 0 | X11: =TK!H25 -> 0 | Y11: =IFERROR(X11/TK!H25,0) -> 0 | AD11: =R11+T11+V11+X11+Z11+AB11 -> 0 | AE11: =IFERROR(AD11/(R11+T11+V11+X11),0) -> 0 | AG11: =AMAZON!J50 -> 0 | AH11: =IFERROR(AG11/AMAZON!J50,0) -> 0 | AI11: =TEMU!J25 -> 0 | AJ11: =IFERROR(AI11/TEMU!J25,0) -> 0 | AK11: =SHEIN!J20 -> 0 | AL11: =IFERROR(AK11/SHEIN!J20,0) -> 0 | AM11: =TK!J25 -> 0 | AN11: =IFERROR(AM11/TK!J25,0) -> 0 | AS11: =AG11+AI11+AK11+AM11+AO11+AQ11 -> 0 | AT11: =IFERROR(AS11/(AG11+AI11+AK11+AM11),0) -> 0 | AU11: =IFERROR((AS11-AD11)/AD11,0) -> 0 | AV11: =AMAZON!L50 -> 0 | AW11: =IFERROR(AV11/AMAZON!L50,0) -> 0 | AX11: =TEMU!L25 -> 0 | AY11: =IFERROR(AX11/TEMU!L25,0) -> 0 | AZ11: =SHEIN!L20 -> 0 | BA11: =IFERROR(AZ11/SHEIN!L20,0) -> 0 | BB11: =TK!L25 -> 0 | BC11: =IFERROR(BB11/TK!L25,0) -> 0 | BH11: =AV11+AX11+AZ11+BB11+BD11+BF11 -> 0 | BI11: =IFERROR(BH11/(AV11+AX11+AZ11+BB11),0) -> 0 | BJ11: =IFERROR((BH11-AS11)/AS11,0) -> 0 | BK11: =AMAZON!N50 -> 0 | BL11: =IFERROR(BK11/AMAZON!N50,0) -> 0 | BM11: =TEMU!N25 -> 0 | BN11: =IFERROR(BM11/TEMU!N25,0) -> 0 | BO11: =SHEIN!N20 -> 0 | BP11: =IFERROR(BO11/SHEIN!N20,0) -> 0 | BQ11: =TK!N25 -> 0 | BR11: =IFERROR(BQ11/TK!N25,0) -> 0 | BW11: =BK11+BM11+BO11+BQ11+BS11+BU11 -> 0 | BX11: =IFERROR(BW11/(BK11+BM11+BO11+BQ11),0) -> 0 | BY11: =IFERROR((BW11-BH11)/BH11,0) -> 0 | BZ11: =AMAZON!P50 -> 0 | CA11: =IFERROR(BZ11/AMAZON!P50,0) -> 0 | CB11: =TEMU!P25 -> 0 | CC11: =IFERROR(CB11/TEMU!P25,0) -> 0 | CD11: =SHEIN!P20 -> 0 | CE11: =IFERROR(CD11/SHEIN!P20,0) -> 0 | CF11: =TK!P25 -> 0 | CG11: =IFERROR(CF11/TK!P25,0) -> 0 | CL11: =BZ11+CB11+CD11+CF11+CH11+CJ11 -> 0 | CM11: =IFERROR(CL11/(BZ11+CB11+CD11+CF11),0) -> 0 | CN11: =IFERROR((CL11-BW11)/BW11,0) -> 0 | CO11: =AMAZON!R50 -> 0 | CP11: =IFERROR(CO11/AMAZON!R50,0) -> 0 | CQ11: =TEMU!R25 -> 0 | CR11: =IFERROR(CQ11/TEMU!R25,0) -> 0 | CS11: =SHEIN!R20 -> 0 | CT11: =IFERROR(CS11/SHEIN!R20,0) -> 0 | CU11: =TK!R25 -> 0 | CV11: =IFERROR(CU11/TK!R25,0) -> 0 | DA11: =CO11+CQ11+CS11+CU11+CW11+CY11 -> 0 | DB11: =IFERROR(DA11/(CO11+CQ11+CS11+CU11),0) -> 0 | DC11: =IFERROR((DA11-CL11)/CL11,0) -> 0 | DD11: =AMAZON!T50 -> 0 | DE11: =IFERROR(DD11/AMAZON!T50,0) -> 0 | DF11: =TEMU!T25 -> 0 | DG11: =IFERROR(DF11/TEMU!T25,0) -> 0 | DH11: =SHEIN!T20 -> 0 | DI11: =IFERROR(DH11/SHEIN!T20,0) -> 0 | DJ11: =TK!T25 -> 0 | DK11: =IFERROR(DJ11/TK!T25,0) -> 0 | DP11: =DD11+DF11+DH11+DJ11+DL11+DN11 -> 0 | DQ11: =IFERROR(DP11/(DD11+DF11+DH11+DJ11),0) -> 0 | DR11: =IFERROR((DP11-DA11)/DA11,0) -> 0 | DS11: =AMAZON!V50 -> 0 | DT11: =IFERROR(DS11/AMAZON!V50,0) -> 0 | DU11: =TEMU!V25 -> 0 | DV11: =IFERROR(DU11/TEMU!V25,0) -> 0 | DW11: =SHEIN!V20 -> 0 | DX11: =IFERROR(DW11/SHEIN!V20,0) -> 0 | DY11: =TK!V25 -> 0 | DZ11: =IFERROR(DY11/TK!V25,0) -> 0 | EE11: =DS11+DU11+DW11+DY11+EA11+EC11 -> 0 | EF11: =IFERROR(EE11/(DS11+DU11+DW11+DY11),0) -> 0 | EG11: =IFERROR((EE11-DP11)/DP11,0) -> 0 | EH11: =AMAZON!X50 -> 0 | EI11: =IFERROR(EH11/AMAZON!X50,0) -> 0 | EJ11: =TEMU!X25 -> 0 | EK11: =IFERROR(EJ11/TEMU!X25,0) -> 0 | EL11: =SHEIN!X20 -> 0 | EM11: =IFERROR(EL11/SHEIN!X20,0) -> 0 | EN11: =TK!X25 -> 0 | EO11: =IFERROR(EN11/TK!X25,0) -> 0 | ET11: =EH11+EJ11+EL11+EN11+EP11+ER11 -> 0 | EU11: =IFERROR(ET11/(EH11+EJ11+EL11+EN11),0) -> 0 | EV11: =IFERROR((ET11-EE11)/EE11,0) -> 0 | EW11: =AMAZON!Z50 -> 0 | EX11: =IFERROR(EW11/AMAZON!Z50,0) -> 0 | EY11: =TEMU!Z25 -> 0 | EZ11: =IFERROR(EY11/TEMU!Z25,0) -> 0 | FA11: =SHEIN!Z20 -> 0 | FB11: =IFERROR(FA11/SHEIN!Z20,0) -> 0 | FC11: =TK!Z25 -> 0 | FD11: =IFERROR(FC11/TK!Z25,0) -> 0 | FI11: =EW11+EY11+FA11+FC11+FE11+FG11 -> 0 | FJ11: =IFERROR(FI11/(EW11+EY11+FA11+FC11),0) -> 0 | FK11: =IFERROR((FI11-ET11)/ET11,0) -> 0 | FL11: =AMAZON!AB50 -> 0 | FM11: =IFERROR(FL11/AMAZON!AB50,0) -> 0 | FN11: =TEMU!AB25 -> 0 | FO11: =IFERROR(FN11/TEMU!AB25,0) -> 0 | FP11: =SHEIN!AB20 -> 0 | FQ11: =IFERROR(FP11/SHEIN!AB20,0) -> 0 | FR11: =TK!AB25 -> 0 | FS11: =IFERROR(FR11/TK!AB25,0) -> 0 | FX11: =FL11+FN11+FP11+FR11+FT11+FV11 -> 0 | FY11: =IFERROR(FX11/(FL11+FN11+FP11+FR11),0) -> 0 | FZ11: =IFERROR((FX11-FI11)/FI11,0) -> 0 | GA11: =AMAZON!AD50 -> 0 | GB11: =IFERROR(GA11/AMAZON!AD50,0) -> 0 | GC11: =TEMU!AD25 -> 0 | GD11: =IFERROR(GC11/TEMU!AD25,0) -> 0 | GE11: =SHEIN!AD20 -> 0 | GF11: =IFERROR(GE11/SHEIN!AD20,0) -> 0 | GG11: =TK!AD25 -> 0 | GH11: =IFERROR(GG11/TK!AD25,0) -> 0 | GM11: =GA11+GC11+GE11+GG11+GI11+GK11 -> 0 | GN11: =IFERROR(GM11/(GA11+GC11+GE11+GG11),0) -> 0 | GO11: =IFERROR((GM11-FX11)/FX11,0) -> 0
A12: 经营销售 | B12: 促销折扣 | C12: 元 | D12: =AMAZON!F59 -> 0 | E12: =IFERROR(D12/AMAZON!F50,0) -> 0 | F12: =TEMU!F29 -> 0 | G12: =IFERROR(F12/TEMU!F25,0) -> 0 | H12: =SHEIN!F23 -> 0 | I12: =IFERROR(H12/SHEIN!F20,0) -> 0 | J12: =TK!F29 -> 0 | K12: =IFERROR(J12/TK!F25,0) -> 0 | P12: =D12+F12+H12+J12+L12+N12 -> 0 | Q12: =IFERROR(P12/(D11+F11+H11+J11),0) -> 0 | R12: =AMAZON!H59 -> 0 | S12: =IFERROR(R12/AMAZON!H50,0) -> 0 | T12: =TEMU!H29 -> 0 | U12: =IFERROR(T12/TEMU!H25,0) -> 0 | V12: =SHEIN!H23 -> 0 | W12: =IFERROR(V12/SHEIN!H20,0) -> 0 | X12: =TK!H29 -> 0 | Y12: =IFERROR(X12/TK!H25,0) -> 0 | AD12: =R12+T12+V12+X12+Z12+AB12 -> 0 | AE12: =IFERROR(AD12/(R11+T11+V11+X11),0) -> 0 | AG12: =AMAZON!J59 -> 0 | AH12: =IFERROR(AG12/AMAZON!J50,0) -> 0 | AI12: =TEMU!J29 -> 0 | AJ12: =IFERROR(AI12/TEMU!J25,0) -> 0 | AK12: =SHEIN!J23 -> 0 | AL12: =IFERROR(AK12/SHEIN!J20,0) -> 0 | AM12: =TK!J29 -> 0 | AN12: =IFERROR(AM12/TK!J25,0) -> 0 | AS12: =AG12+AI12+AK12+AM12+AO12+AQ12 -> 0 | AT12: =IFERROR(AS12/(AG11+AI11+AK11+AM11),0) -> 0 | AU12: =IFERROR((AS12-AD12)/AD12,0) -> 0 | AV12: =AMAZON!L59 -> 0 | AW12: =IFERROR(AV12/AMAZON!L50,0) -> 0 | AX12: =TEMU!L29 -> 0 | AY12: =IFERROR(AX12/TEMU!L25,0) -> 0 | AZ12: =SHEIN!L23 -> 0 | BA12: =IFERROR(AZ12/SHEIN!L20,0) -> 0 | BB12: =TK!L29 -> 0 | BC12: =IFERROR(BB12/TK!L25,0) -> 0 | BH12: =AV12+AX12+AZ12+BB12+BD12+BF12 -> 0 | BI12: =IFERROR(BH12/(AV11+AX11+AZ11+BB11),0) -> 0 | BJ12: =IFERROR((BH12-AS12)/AS12,0) -> 0 | BK12: =AMAZON!N59 -> 0 | BL12: =IFERROR(BK12/AMAZON!N50,0) -> 0 | BM12: =TEMU!N29 -> 0 | BN12: =IFERROR(BM12/TEMU!N25,0) -> 0 | BO12: =SHEIN!N23 -> 0 | BP12: =IFERROR(BO12/SHEIN!N20,0) -> 0 | BQ12: =TK!N29 -> 0 | BR12: =IFERROR(BQ12/TK!N25,0) -> 0 | BW12: =BK12+BM12+BO12+BQ12+BS12+BU12 -> 0 | BX12: =IFERROR(BW12/(BK11+BM11+BO11+BQ11),0) -> 0 | BY12: =IFERROR((BW12-BH12)/BH12,0) -> 0 | BZ12: =AMAZON!P59 -> 0 | CA12: =IFERROR(BZ12/AMAZON!P50,0) -> 0 | CB12: =TEMU!P29 -> 0 | CC12: =IFERROR(CB12/TEMU!P25,0) -> 0 | CD12: =SHEIN!P23 -> 0 | CE12: =IFERROR(CD12/SHEIN!P20,0) -> 0 | CF12: =TK!P29 -> 0 | CG12: =IFERROR(CF12/TK!P25,0) -> 0 | CL12: =BZ12+CB12+CD12+CF12+CH12+CJ12 -> 0 | CM12: =IFERROR(CL12/(BZ11+CB11+CD11+CF11),0) -> 0 | CN12: =IFERROR((CL12-BW12)/BW12,0) -> 0 | CO12: =AMAZON!R59 -> 0 | CP12: =IFERROR(CO12/AMAZON!R50,0) -> 0 | CQ12: =TEMU!R29 -> 0 | CR12: =IFERROR(CQ12/TEMU!R25,0) -> 0 | CS12: =SHEIN!R23 -> 0 | CT12: =IFERROR(CS12/SHEIN!R20,0) -> 0 | CU12: =TK!R29 -> 0 | CV12: =IFERROR(CU12/TK!R25,0) -> 0 | DA12: =CO12+CQ12+CS12+CU12+CW12+CY12 -> 0 | DB12: =IFERROR(DA12/(CO11+CQ11+CS11+CU11),0) -> 0 | DC12: =IFERROR((DA12-CL12)/CL12,0) -> 0 | DD12: =AMAZON!T59 -> 0 | DE12: =IFERROR(DD12/AMAZON!T50,0) -> 0 | DF12: =TEMU!T29 -> 0 | DG12: =IFERROR(DF12/TEMU!T25,0) -> 0 | DH12: =SHEIN!T23 -> 0 | DI12: =IFERROR(DH12/SHEIN!T20,0) -> 0 | DJ12: =TK!T29 -> 0 | DK12: =IFERROR(DJ12/TK!T25,0) -> 0 | DP12: =DD12+DF12+DH12+DJ12+DL12+DN12 -> 0 | DQ12: =IFERROR(DP12/(DD11+DF11+DH11+DJ11),0) -> 0 | DR12: =IFERROR((DP12-DA12)/DA12,0) -> 0 | DS12: =AMAZON!V59 -> 0 | DT12: =IFERROR(DS12/AMAZON!V50,0) -> 0 | DU12: =TEMU!V29 -> 0 | DV12: =IFERROR(DU12/TEMU!V25,0) -> 0 | DW12: =SHEIN!V23 -> 0 | DX12: =IFERROR(DW12/SHEIN!V20,0) -> 0 | DY12: =TK!V29 -> 0 | DZ12: =IFERROR(DY12/TK!V25,0) -> 0 | EE12: =DS12+DU12+DW12+DY12+EA12+EC12 -> 0 | EF12: =IFERROR(EE12/(DS11+DU11+DW11+DY11),0) -> 0 | EG12: =IFERROR((EE12-DP12)/DP12,0) -> 0 | EH12: =AMAZON!X59 -> 0 | EI12: =IFERROR(EH12/AMAZON!X50,0) -> 0 | EJ12: =TEMU!X29 -> 0 | EK12: =IFERROR(EJ12/TEMU!X25,0) -> 0 | EL12: =SHEIN!X23 -> 0 | EM12: =IFERROR(EL12/SHEIN!X20,0) -> 0 | EN12: =TK!X29 -> 0 | EO12: =IFERROR(EN12/TK!X25,0) -> 0 | ET12: =EH12+EJ12+EL12+EN12+EP12+ER12 -> 0 | EU12: =IFERROR(ET12/(EH11+EJ11+EL11+EN11),0) -> 0 | EV12: =IFERROR((ET12-EE12)/EE12,0) -> 0 | EW12: =AMAZON!Z59 -> 0 | EX12: =IFERROR(EW12/AMAZON!Z50,0) -> 0 | EY12: =TEMU!Z29 -> 0 | EZ12: =IFERROR(EY12/TEMU!Z25,0) -> 0 | FA12: =SHEIN!Z23 -> 0 | FB12: =IFERROR(FA12/SHEIN!Z20,0) -> 0 | FC12: =TK!Z29 -> 0 | FD12: =IFERROR(FC12/TK!Z25,0) -> 0 | FI12: =EW12+EY12+FA12+FC12+FE12+FG12 -> 0 | FJ12: =IFERROR(FI12/(EW11+EY11+FA11+FC11),0) -> 0 | FK12: =IFERROR((FI12-ET12)/ET12,0) -> 0 | FL12: =AMAZON!AB59 -> 0 | FM12: =IFERROR(FL12/AMAZON!AB50,0) -> 0 | FN12: =TEMU!AB29 -> 0 | FO12: =IFERROR(FN12/TEMU!AB25,0) -> 0 | FP12: =SHEIN!AB23 -> 0 | FQ12: =IFERROR(FP12/SHEIN!AB20,0) -> 0 | FR12: =TK!AB29 -> 0 | FS12: =IFERROR(FR12/TK!AB25,0) -> 0 | FX12: =FL12+FN12+FP12+FR12+FT12+FV12 -> 0 | FY12: =IFERROR(FX12/(FL11+FN11+FP11+FR11),0) -> 0 | FZ12: =IFERROR((FX12-FI12)/FI12,0) -> 0 | GA12: =AMAZON!AD59 -> 0 | GB12: =IFERROR(GA12/AMAZON!AD50,0) -> 0 | GC12: =TEMU!AD29 -> 0 | GD12: =IFERROR(GC12/TEMU!AD25,0) -> 0 | GE12: =SHEIN!AD23 -> 0 | GF12: =IFERROR(GE12/SHEIN!AD20,0) -> 0 | GG12: =TK!AD29 -> 0 | GH12: =IFERROR(GG12/TK!AD25,0) -> 0 | GM12: =GA12+GC12+GE12+GG12+GI12+GK12 -> 0 | GN12: =IFERROR(GM12/(GA11+GC11+GE11+GG11),0) -> 0 | GO12: =IFERROR((GM12-FX12)/FX12,0) -> 0
A13: 经营退款 | C13: 元 | D13: =AMAZON!F68 -> 0 | E13: =IFERROR(D13/AMAZON!F50,0) -> 0 | F13: =TEMU!F33 -> 0 | G13: =IFERROR(F13/TEMU!F25,0) -> 0 | H13: =SHEIN!F26 -> 0 | I13: =IFERROR(H13/SHEIN!F20,0) -> 0 | J13: =TK!F33 -> 0 | K13: =IFERROR(J13/TK!F25,0) -> 0 | P13: =D13+F13+H13+J13+L13+N13 -> 0 | Q13: =IFERROR(P13/(D11+F11+H11+J11),0) -> 0 | R13: =AMAZON!H68 -> 0 | S13: =IFERROR(R13/AMAZON!H50,0) -> 0 | T13: =TEMU!H33 -> 0 | U13: =IFERROR(T13/TEMU!H25,0) -> 0 | V13: =SHEIN!H26 -> 0 | W13: =IFERROR(V13/SHEIN!H20,0) -> 0 | X13: =TK!H33 -> 0 | Y13: =IFERROR(X13/TK!H25,0) -> 0 | AD13: =R13+T13+V13+X13+Z13+AB13 -> 0 | AE13: =IFERROR(AD13/(R11+T11+V11+X11),0) -> 0 | AG13: =AMAZON!J68 -> 0 | AH13: =IFERROR(AG13/AMAZON!J50,0) -> 0 | AI13: =TEMU!J33 -> 0 | AJ13: =IFERROR(AI13/TEMU!J25,0) -> 0 | AK13: =SHEIN!J26 -> 0 | AL13: =IFERROR(AK13/SHEIN!J20,0) -> 0 | AM13: =TK!J33 -> 0 | AN13: =IFERROR(AM13/TK!J25,0) -> 0 | AS13: =AG13+AI13+AK13+AM13+AO13+AQ13 -> 0 | AT13: =IFERROR(AS13/(AG11+AI11+AK11+AM11),0) -> 0 | AU13: =IFERROR((AS13-AD13)/AD13,0) -> 0 | AV13: =AMAZON!L68 -> 0 | AW13: =IFERROR(AV13/AMAZON!L50,0) -> 0 | AX13: =TEMU!L33 -> 0 | AY13: =IFERROR(AX13/TEMU!L25,0) -> 0 | AZ13: =SHEIN!L26 -> 0 | BA13: =IFERROR(AZ13/SHEIN!L20,0) -> 0 | BB13: =TK!L33 -> 0 | BC13: =IFERROR(BB13/TK!L25,0) -> 0 | BH13: =AV13+AX13+AZ13+BB13+BD13+BF13 -> 0 | BI13: =IFERROR(BH13/(AV11+AX11+AZ11+BB11),0) -> 0 | BJ13: =IFERROR((BH13-AS13)/AS13,0) -> 0 | BK13: =AMAZON!N68 -> 0 | BL13: =IFERROR(BK13/AMAZON!N50,0) -> 0 | BM13: =TEMU!N33 -> 0 | BN13: =IFERROR(BM13/TEMU!N25,0) -> 0 | BO13: =SHEIN!N26 -> 0 | BP13: =IFERROR(BO13/SHEIN!N20,0) -> 0 | BQ13: =TK!N33 -> 0 | BR13: =IFERROR(BQ13/TK!N25,0) -> 0 | BW13: =BK13+BM13+BO13+BQ13+BS13+BU13 -> 0 | BX13: =IFERROR(BW13/(BK11+BM11+BO11+BQ11),0) -> 0 | BY13: =IFERROR((BW13-BH13)/BH13,0) -> 0 | BZ13: =AMAZON!P68 -> 0 | CA13: =IFERROR(BZ13/AMAZON!P50,0) -> 0 | CB13: =TEMU!P33 -> 0 | CC13: =IFERROR(CB13/TEMU!P25,0) -> 0 | CD13: =SHEIN!P26 -> 0 | CE13: =IFERROR(CD13/SHEIN!P20,0) -> 0 | CF13: =TK!P33 -> 0 | CG13: =IFERROR(CF13/TK!P25,0) -> 0 | CL13: =BZ13+CB13+CD13+CF13+CH13+CJ13 -> 0 | CM13: =IFERROR(CL13/(BZ11+CB11+CD11+CF11),0) -> 0 | CN13: =IFERROR((CL13-BW13)/BW13,0) -> 0 | CO13: =AMAZON!R68 -> 0 | CP13: =IFERROR(CO13/AMAZON!R50,0) -> 0 | CQ13: =TEMU!R33 -> 0 | CR13: =IFERROR(CQ13/TEMU!R25,0) -> 0 | CS13: =SHEIN!R26 -> 0 | CT13: =IFERROR(CS13/SHEIN!R20,0) -> 0 | CU13: =TK!R33 -> 0 | CV13: =IFERROR(CU13/TK!R25,0) -> 0 | DA13: =CO13+CQ13+CS13+CU13+CW13+CY13 -> 0 | DB13: =IFERROR(DA13/(CO11+CQ11+CS11+CU11),0) -> 0 | DC13: =IFERROR((DA13-CL13)/CL13,0) -> 0 | DD13: =AMAZON!T68 -> 0 | DE13: =IFERROR(DD13/AMAZON!T50,0) -> 0 | DF13: =TEMU!T33 -> 0 | DG13: =IFERROR(DF13/TEMU!T25,0) -> 0 | DH13: =SHEIN!T26 -> 0 | DI13: =IFERROR(DH13/SHEIN!T20,0) -> 0 | DJ13: =TK!T33 -> 0 | DK13: =IFERROR(DJ13/TK!T25,0) -> 0 | DP13: =DD13+DF13+DH13+DJ13+DL13+DN13 -> 0 | DQ13: =IFERROR(DP13/(DD11+DF11+DH11+DJ11),0) -> 0 | DR13: =IFERROR((DP13-DA13)/DA13,0) -> 0 | DS13: =AMAZON!V68 -> 0 | DT13: =IFERROR(DS13/AMAZON!V50,0) -> 0 | DU13: =TEMU!V33 -> 0 | DV13: =IFERROR(DU13/TEMU!V25,0) -> 0 | DW13: =SHEIN!V26 -> 0 | DX13: =IFERROR(DW13/SHEIN!V20,0) -> 0 | DY13: =TK!V33 -> 0 | DZ13: =IFERROR(DY13/TK!V25,0) -> 0 | EE13: =DS13+DU13+DW13+DY13+EA13+EC13 -> 0 | EF13: =IFERROR(EE13/(DS11+DU11+DW11+DY11),0) -> 0 | EG13: =IFERROR((EE13-DP13)/DP13,0) -> 0 | EH13: =AMAZON!X68 -> 0 | EI13: =IFERROR(EH13/AMAZON!X50,0) -> 0 | EJ13: =TEMU!X33 -> 0 | EK13: =IFERROR(EJ13/TEMU!X25,0) -> 0 | EL13: =SHEIN!X26 -> 0 | EM13: =IFERROR(EL13/SHEIN!X20,0) -> 0 | EN13: =TK!X33 -> 0 | EO13: =IFERROR(EN13/TK!X25,0) -> 0 | ET13: =EH13+EJ13+EL13+EN13+EP13+ER13 -> 0 | EU13: =IFERROR(ET13/(EH11+EJ11+EL11+EN11),0) -> 0 | EV13: =IFERROR((ET13-EE13)/EE13,0) -> 0 | EW13: =AMAZON!Z68 -> 0 | EX13: =IFERROR(EW13/AMAZON!Z50,0) -> 0 | EY13: =TEMU!Z33 -> 0 | EZ13: =IFERROR(EY13/TEMU!Z25,0) -> 0 | FA13: =SHEIN!Z26 -> 0 | FB13: =IFERROR(FA13/SHEIN!Z20,0) -> 0 | FC13: =TK!Z33 -> 0 | FD13: =IFERROR(FC13/TK!Z25,0) -> 0 | FI13: =EW13+EY13+FA13+FC13+FE13+FG13 -> 0 | FJ13: =IFERROR(FI13/(EW11+EY11+FA11+FC11),0) -> 0 | FK13: =IFERROR((FI13-ET13)/ET13,0) -> 0 | FL13: =AMAZON!AB68 -> 0 | FM13: =IFERROR(FL13/AMAZON!AB50,0) -> 0 | FN13: =TEMU!AB33 -> 0 | FO13: =IFERROR(FN13/TEMU!AB25,0) -> 0 | FP13: =SHEIN!AB26 -> 0 | FQ13: =IFERROR(FP13/SHEIN!AB20,0) -> 0 | FR13: =TK!AB33 -> 0 | FS13: =IFERROR(FR13/TK!AB25,0) -> 0 | FX13: =FL13+FN13+FP13+FR13+FT13+FV13 -> 0 | FY13: =IFERROR(FX13/(FL11+FN11+FP11+FR11),0) -> 0 | FZ13: =IFERROR((FX13-FI13)/FI13,0) -> 0 | GA13: =AMAZON!AD68 -> 0 | GB13: =IFERROR(GA13/AMAZON!AD50,0) -> 0 | GC13: =TEMU!AD33 -> 0 | GD13: =IFERROR(GC13/TEMU!AD25,0) -> 0 | GE13: =SHEIN!AD26 -> 0 | GF13: =IFERROR(GE13/SHEIN!AD20,0) -> 0 | GG13: =TK!AD33 -> 0 | GH13: =IFERROR(GG13/TK!AD25,0) -> 0 | GM13: =GA13+GC13+GE13+GG13+GI13+GK13 -> 0 | GN13: =IFERROR(GM13/(GA11+GC11+GE11+GG11),0) -> 0 | GO13: =IFERROR((GM13-FX13)/FX13,0) -> 0
A14: 经营退款 | B14: 销售退款 | C14: 元 | D14: =AMAZON!F69 -> 0 | E14: =IFERROR(D14/AMAZON!F50,0) -> 0 | F14: =TEMU!F34 -> 0 | G14: =IFERROR(F14/TEMU!F25,0) -> 0 | H14: =SHEIN!F27 -> 0 | I14: =IFERROR(H14/SHEIN!F20,0) -> 0 | J14: =TK!F34 -> 0 | K14: =IFERROR(J14/TK!F25,0) -> 0 | P14: =D14+F14+H14+J14+L14+N14 -> 0 | Q14: =IFERROR(P14/(D11+F11+H11+J11),0) -> 0 | R14: =AMAZON!H69 -> 0 | S14: =IFERROR(R14/AMAZON!H50,0) -> 0 | T14: =TEMU!H34 -> 0 | U14: =IFERROR(T14/TEMU!H25,0) -> 0 | V14: =SHEIN!H27 -> 0 | W14: =IFERROR(V14/SHEIN!H20,0) -> 0 | X14: =TK!H34 -> 0 | Y14: =IFERROR(X14/TK!H25,0) -> 0 | AD14: =R14+T14+V14+X14+Z14+AB14 -> 0 | AE14: =IFERROR(AD14/(R11+T11+V11+X11),0) -> 0 | AG14: =AMAZON!J69 -> 0 | AH14: =IFERROR(AG14/AMAZON!J50,0) -> 0 | AI14: =TEMU!J34 -> 0 | AJ14: =IFERROR(AI14/TEMU!J25,0) -> 0 | AK14: =SHEIN!J27 -> 0 | AL14: =IFERROR(AK14/SHEIN!J20,0) -> 0 | AM14: =TK!J34 -> 0 | AN14: =IFERROR(AM14/TK!J25,0) -> 0 | AS14: =AG14+AI14+AK14+AM14+AO14+AQ14 -> 0 | AT14: =IFERROR(AS14/(AG11+AI11+AK11+AM11),0) -> 0 | AU14: =IFERROR((AS14-AD14)/AD14,0) -> 0 | AV14: =AMAZON!L69 -> 0 | AW14: =IFERROR(AV14/AMAZON!L50,0) -> 0 | AX14: =TEMU!L34 -> 0 | AY14: =IFERROR(AX14/TEMU!L25,0) -> 0 | AZ14: =SHEIN!L27 -> 0 | BA14: =IFERROR(AZ14/SHEIN!L20,0) -> 0 | BB14: =TK!L34 -> 0 | BC14: =IFERROR(BB14/TK!L25,0) -> 0 | BH14: =AV14+AX14+AZ14+BB14+BD14+BF14 -> 0 | BI14: =IFERROR(BH14/(AV11+AX11+AZ11+BB11),0) -> 0 | BJ14: =IFERROR((BH14-AS14)/AS14,0) -> 0 | BK14: =AMAZON!N69 -> 0 | BL14: =IFERROR(BK14/AMAZON!N50,0) -> 0 | BM14: =TEMU!N34 -> 0 | BN14: =IFERROR(BM14/TEMU!N25,0) -> 0 | BO14: =SHEIN!N27 -> 0 | BP14: =IFERROR(BO14/SHEIN!N20,0) -> 0 | BQ14: =TK!N34 -> 0 | BR14: =IFERROR(BQ14/TK!N25,0) -> 0 | BW14: =BK14+BM14+BO14+BQ14+BS14+BU14 -> 0 | BX14: =IFERROR(BW14/(BK11+BM11+BO11+BQ11),0) -> 0 | BY14: =IFERROR((BW14-BH14)/BH14,0) -> 0 | BZ14: =AMAZON!P69 -> 0 | CA14: =IFERROR(BZ14/AMAZON!P50,0) -> 0 | CB14: =TEMU!P34 -> 0 | CC14: =IFERROR(CB14/TEMU!P25,0) -> 0 | CD14: =SHEIN!P27 -> 0 | CE14: =IFERROR(CD14/SHEIN!P20,0) -> 0 | CF14: =TK!P34 -> 0 | CG14: =IFERROR(CF14/TK!P25,0) -> 0 | CL14: =BZ14+CB14+CD14+CF14+CH14+CJ14 -> 0 | CM14: =IFERROR(CL14/(BZ11+CB11+CD11+CF11),0) -> 0 | CN14: =IFERROR((CL14-BW14)/BW14,0) -> 0 | CO14: =AMAZON!R69 -> 0 | CP14: =IFERROR(CO14/AMAZON!R50,0) -> 0 | CQ14: =TEMU!R34 -> 0 | CR14: =IFERROR(CQ14/TEMU!R25,0) -> 0 | CS14: =SHEIN!R27 -> 0 | CT14: =IFERROR(CS14/SHEIN!R20,0) -> 0 | CU14: =TK!R34 -> 0 | CV14: =IFERROR(CU14/TK!R25,0) -> 0 | DA14: =CO14+CQ14+CS14+CU14+CW14+CY14 -> 0 | DB14: =IFERROR(DA14/(CO11+CQ11+CS11+CU11),0) -> 0 | DC14: =IFERROR((DA14-CL14)/CL14,0) -> 0 | DD14: =AMAZON!T69 -> 0 | DE14: =IFERROR(DD14/AMAZON!T50,0) -> 0 | DF14: =TEMU!T34 -> 0 | DG14: =IFERROR(DF14/TEMU!T25,0) -> 0 | DH14: =SHEIN!T27 -> 0 | DI14: =IFERROR(DH14/SHEIN!T20,0) -> 0 | DJ14: =TK!T34 -> 0 | DK14: =IFERROR(DJ14/TK!T25,0) -> 0 | DP14: =DD14+DF14+DH14+DJ14+DL14+DN14 -> 0 | DQ14: =IFERROR(DP14/(DD11+DF11+DH11+DJ11),0) -> 0 | DR14: =IFERROR((DP14-DA14)/DA14,0) -> 0 | DS14: =AMAZON!V69 -> 0 | DT14: =IFERROR(DS14/AMAZON!V50,0) -> 0 | DU14: =TEMU!V34 -> 0 | DV14: =IFERROR(DU14/TEMU!V25,0) -> 0 | DW14: =SHEIN!V27 -> 0 | DX14: =IFERROR(DW14/SHEIN!V20,0) -> 0 | DY14: =TK!V34 -> 0 | DZ14: =IFERROR(DY14/TK!V25,0) -> 0 | EE14: =DS14+DU14+DW14+DY14+EA14+EC14 -> 0 | EF14: =IFERROR(EE14/(DS11+DU11+DW11+DY11),0) -> 0 | EG14: =IFERROR((EE14-DP14)/DP14,0) -> 0 | EH14: =AMAZON!X69 -> 0 | EI14: =IFERROR(EH14/AMAZON!X50,0) -> 0 | EJ14: =TEMU!X34 -> 0 | EK14: =IFERROR(EJ14/TEMU!X25,0) -> 0 | EL14: =SHEIN!X27 -> 0 | EM14: =IFERROR(EL14/SHEIN!X20,0) -> 0 | EN14: =TK!X34 -> 0 | EO14: =IFERROR(EN14/TK!X25,0) -> 0 | ET14: =EH14+EJ14+EL14+EN14+EP14+ER14 -> 0 | EU14: =IFERROR(ET14/(EH11+EJ11+EL11+EN11),0) -> 0 | EV14: =IFERROR((ET14-EE14)/EE14,0) -> 0 | EW14: =AMAZON!Z69 -> 0 | EX14: =IFERROR(EW14/AMAZON!Z50,0) -> 0 | EY14: =TEMU!Z34 -> 0 | EZ14: =IFERROR(EY14/TEMU!Z25,0) -> 0 | FA14: =SHEIN!Z27 -> 0 | FB14: =IFERROR(FA14/SHEIN!Z20,0) -> 0 | FC14: =TK!Z34 -> 0 | FD14: =IFERROR(FC14/TK!Z25,0) -> 0 | FI14: =EW14+EY14+FA14+FC14+FE14+FG14 -> 0 | FJ14: =IFERROR(FI14/(EW11+EY11+FA11+FC11),0) -> 0 | FK14: =IFERROR((FI14-ET14)/ET14,0) -> 0 | FL14: =AMAZON!AB69 -> 0 | FM14: =IFERROR(FL14/AMAZON!AB50,0) -> 0 | FN14: =TEMU!AB34 -> 0 | FO14: =IFERROR(FN14/TEMU!AB25,0) -> 0 | FP14: =SHEIN!AB27 -> 0 | FQ14: =IFERROR(FP14/SHEIN!AB20,0) -> 0 | FR14: =TK!AB34 -> 0 | FS14: =IFERROR(FR14/TK!AB25,0) -> 0 | FX14: =FL14+FN14+FP14+FR14+FT14+FV14 -> 0 | FY14: =IFERROR(FX14/(FL11+FN11+FP11+FR11),0) -> 0 | FZ14: =IFERROR((FX14-FI14)/FI14,0) -> 0 | GA14: =AMAZON!AD69 -> 0 | GB14: =IFERROR(GA14/AMAZON!AD50,0) -> 0 | GC14: =TEMU!AD34 -> 0 | GD14: =IFERROR(GC14/TEMU!AD25,0) -> 0 | GE14: =SHEIN!AD27 -> 0 | GF14: =IFERROR(GE14/SHEIN!AD20,0) -> 0 | GG14: =TK!AD34 -> 0 | GH14: =IFERROR(GG14/TK!AD25,0) -> 0 | GM14: =GA14+GC14+GE14+GG14+GI14+GK14 -> 0 | GN14: =IFERROR(GM14/(GA11+GC11+GE11+GG11),0) -> 0 | GO14: =IFERROR((GM14-FX14)/FX14,0) -> 0
A15: 经营退款 | B15: 退款损失 | C15: 元 | D15: =AMAZON!F78 -> 0 | E15: =IFERROR(D15/AMAZON!F50,0) -> 0 | F15: =TEMU!F38 -> 0 | G15: =IFERROR(F15/TEMU!F25,0) -> 0 | H15: =SHEIN!F30 -> 0 | I15: =IFERROR(H15/SHEIN!F20,0) -> 0 | J15: =TK!F38 -> 0 | K15: =IFERROR(J15/TK!F25,0) -> 0 | P15: =D15+F15+H15+J15+L15+N15 -> 0 | Q15: =IFERROR(P15/(D11+F11+H11+J11),0) -> 0 | R15: =AMAZON!H78 -> 0 | S15: =IFERROR(R15/AMAZON!H50,0) -> 0 | T15: =TEMU!H38 -> 0 | U15: =IFERROR(T15/TEMU!H25,0) -> 0 | V15: =SHEIN!H30 -> 0 | W15: =IFERROR(V15/SHEIN!H20,0) -> 0 | X15: =TK!H38 -> 0 | Y15: =IFERROR(X15/TK!H25,0) -> 0 | AD15: =R15+T15+V15+X15+Z15+AB15 -> 0 | AE15: =IFERROR(AD15/(R11+T11+V11+X11),0) -> 0 | AG15: =AMAZON!J78 -> 0 | AH15: =IFERROR(AG15/AMAZON!J50,0) -> 0 | AI15: =TEMU!J38 -> 0 | AJ15: =IFERROR(AI15/TEMU!J25,0) -> 0 | AK15: =SHEIN!J30 -> 0 | AL15: =IFERROR(AK15/SHEIN!J20,0) -> 0 | AM15: =TK!J38 -> 0 | AN15: =IFERROR(AM15/TK!J25,0) -> 0 | AS15: =AG15+AI15+AK15+AM15+AO15+AQ15 -> 0 | AT15: =IFERROR(AS15/(AG11+AI11+AK11+AM11),0) -> 0 | AU15: =IFERROR((AS15-AD15)/AD15,0) -> 0 | AV15: =AMAZON!L78 -> 0 | AW15: =IFERROR(AV15/AMAZON!L50,0) -> 0 | AX15: =TEMU!L38 -> 0 | AY15: =IFERROR(AX15/TEMU!L25,0) -> 0 | AZ15: =SHEIN!L30 -> 0 | BA15: =IFERROR(AZ15/SHEIN!L20,0) -> 0 | BB15: =TK!L38 -> 0 | BC15: =IFERROR(BB15/TK!L25,0) -> 0 | BH15: =AV15+AX15+AZ15+BB15+BD15+BF15 -> 0 | BI15: =IFERROR(BH15/(AV11+AX11+AZ11+BB11),0) -> 0 | BJ15: =IFERROR((BH15-AS15)/AS15,0) -> 0 | BK15: =AMAZON!N78 -> 0 | BL15: =IFERROR(BK15/AMAZON!N50,0) -> 0 | BM15: =TEMU!N38 -> 0 | BN15: =IFERROR(BM15/TEMU!N25,0) -> 0 | BO15: =SHEIN!N30 -> 0 | BP15: =IFERROR(BO15/SHEIN!N20,0) -> 0 | BQ15: =TK!N38 -> 0 | BR15: =IFERROR(BQ15/TK!N25,0) -> 0 | BW15: =BK15+BM15+BO15+BQ15+BS15+BU15 -> 0 | BX15: =IFERROR(BW15/(BK11+BM11+BO11+BQ11),0) -> 0 | BY15: =IFERROR((BW15-BH15)/BH15,0) -> 0 | BZ15: =AMAZON!P78 -> 0 | CA15: =IFERROR(BZ15/AMAZON!P50,0) -> 0 | CB15: =TEMU!P38 -> 0 | CC15: =IFERROR(CB15/TEMU!P25,0) -> 0 | CD15: =SHEIN!P30 -> 0 | CE15: =IFERROR(CD15/SHEIN!P20,0) -> 0 | CF15: =TK!P38 -> 0 | CG15: =IFERROR(CF15/TK!P25,0) -> 0 | CL15: =BZ15+CB15+CD15+CF15+CH15+CJ15 -> 0 | CM15: =IFERROR(CL15/(BZ11+CB11+CD11+CF11),0) -> 0 | CN15: =IFERROR((CL15-BW15)/BW15,0) -> 0 | CO15: =AMAZON!R78 -> 0 | CP15: =IFERROR(CO15/AMAZON!R50,0) -> 0 | CQ15: =TEMU!R38 -> 0 | CR15: =IFERROR(CQ15/TEMU!R25,0) -> 0 | CS15: =SHEIN!R30 -> 0 | CT15: =IFERROR(CS15/SHEIN!R20,0) -> 0 | CU15: =TK!R38 -> 0 | CV15: =IFERROR(CU15/TK!R25,0) -> 0 | DA15: =CO15+CQ15+CS15+CU15+CW15+CY15 -> 0 | DB15: =IFERROR(DA15/(CO11+CQ11+CS11+CU11),0) -> 0 | DC15: =IFERROR((DA15-CL15)/CL15,0) -> 0 | DD15: =AMAZON!T78 -> 0 | DE15: =IFERROR(DD15/AMAZON!T50,0) -> 0 | DF15: =TEMU!T38 -> 0 | DG15: =IFERROR(DF15/TEMU!T25,0) -> 0 | DH15: =SHEIN!T30 -> 0 | DI15: =IFERROR(DH15/SHEIN!T20,0) -> 0 | DJ15: =TK!T38 -> 0 | DK15: =IFERROR(DJ15/TK!T25,0) -> 0 | DP15: =DD15+DF15+DH15+DJ15+DL15+DN15 -> 0 | DQ15: =IFERROR(DP15/(DD11+DF11+DH11+DJ11),0) -> 0 | DR15: =IFERROR((DP15-DA15)/DA15,0) -> 0 | DS15: =AMAZON!V78 -> 0 | DT15: =IFERROR(DS15/AMAZON!V50,0) -> 0 | DU15: =TEMU!V38 -> 0 | DV15: =IFERROR(DU15/TEMU!V25,0) -> 0 | DW15: =SHEIN!V30 -> 0 | DX15: =IFERROR(DW15/SHEIN!V20,0) -> 0 | DY15: =TK!V38 -> 0 | DZ15: =IFERROR(DY15/TK!V25,0) -> 0 | EE15: =DS15+DU15+DW15+DY15+EA15+EC15 -> 0 | EF15: =IFERROR(EE15/(DS11+DU11+DW11+DY11),0) -> 0 | EG15: =IFERROR((EE15-DP15)/DP15,0) -> 0 | EH15: =AMAZON!X78 -> 0 | EI15: =IFERROR(EH15/AMAZON!X50,0) -> 0 | EJ15: =TEMU!X38 -> 0 | EK15: =IFERROR(EJ15/TEMU!X25,0) -> 0 | EL15: =SHEIN!X30 -> 0 | EM15: =IFERROR(EL15/SHEIN!X20,0) -> 0 | EN15: =TK!X38 -> 0 | EO15: =IFERROR(EN15/TK!X25,0) -> 0 | ET15: =EH15+EJ15+EL15+EN15+EP15+ER15 -> 0 | EU15: =IFERROR(ET15/(EH11+EJ11+EL11+EN11),0) -> 0 | EV15: =IFERROR((ET15-EE15)/EE15,0) -> 0 | EW15: =AMAZON!Z78 -> 0 | EX15: =IFERROR(EW15/AMAZON!Z50,0) -> 0 | EY15: =TEMU!Z38 -> 0 | EZ15: =IFERROR(EY15/TEMU!Z25,0) -> 0 | FA15: =SHEIN!Z30 -> 0 | FB15: =IFERROR(FA15/SHEIN!Z20,0) -> 0 | FC15: =TK!Z38 -> 0 | FD15: =IFERROR(FC15/TK!Z25,0) -> 0 | FI15: =EW15+EY15+FA15+FC15+FE15+FG15 -> 0 | FJ15: =IFERROR(FI15/(EW11+EY11+FA11+FC11),0) -> 0 | FK15: =IFERROR((FI15-ET15)/ET15,0) -> 0 | FL15: =AMAZON!AB78 -> 0 | FM15: =IFERROR(FL15/AMAZON!AB50,0) -> 0 | FN15: =TEMU!AB38 -> 0 | FO15: =IFERROR(FN15/TEMU!AB25,0) -> 0 | FP15: =SHEIN!AB30 -> 0 | FQ15: =IFERROR(FP15/SHEIN!AB20,0) -> 0 | FR15: =TK!AB38 -> 0 | FS15: =IFERROR(FR15/TK!AB25,0) -> 0 | FX15: =FL15+FN15+FP15+FR15+FT15+FV15 -> 0 | FY15: =IFERROR(FX15/(FL11+FN11+FP11+FR11),0) -> 0 | FZ15: =IFERROR((FX15-FI15)/FI15,0) -> 0 | GA15: =AMAZON!AD78 -> 0 | GB15: =IFERROR(GA15/AMAZON!AD50,0) -> 0 | GC15: =TEMU!AD38 -> 0 | GD15: =IFERROR(GC15/TEMU!AD25,0) -> 0 | GE15: =SHEIN!AD30 -> 0 | GF15: =IFERROR(GE15/SHEIN!AD20,0) -> 0 | GG15: =TK!AD38 -> 0 | GH15: =IFERROR(GG15/TK!AD25,0) -> 0 | GM15: =GA15+GC15+GE15+GG15+GI15+GK15 -> 0 | GN15: =IFERROR(GM15/(GA11+GC11+GE11+GG11),0) -> 0 | GO15: =IFERROR((GM15-FX15)/FX15,0) -> 0
A16: 税费 | C16: 元 | D16: =AMAZON!F87 -> 0 | E16: =IFERROR(D16/AMAZON!F50,0) -> 0 | F16: =TEMU!F42 -> 0 | G16: =IFERROR(F16/TEMU!F25,0) -> 0 | H16: =SHEIN!F33 -> 0 | I16: =IFERROR(H16/SHEIN!F20,0) -> 0 | J16: =TK!F42 -> 0 | K16: =IFERROR(J16/TK!F25,0) -> 0 | P16: =D16+F16+H16+J16+L16+N16 -> 0 | Q16: =IFERROR(P16/(D11+F11+H11+J11),0) -> 0 | R16: =AMAZON!H87 -> 0 | S16: =IFERROR(R16/AMAZON!H50,0) -> 0 | T16: =TEMU!H42 -> 0 | U16: =IFERROR(T16/TEMU!H25,0) -> 0 | V16: =SHEIN!H33 -> 0 | W16: =IFERROR(V16/SHEIN!H20,0) -> 0 | X16: =TK!H42 -> 0 | Y16: =IFERROR(X16/TK!H25,0) -> 0 | AD16: =R16+T16+V16+X16+Z16+AB16 -> 0 | AE16: =IFERROR(AD16/(R11+T11+V11+X11),0) -> 0 | AG16: =AMAZON!J87 -> 0 | AH16: =IFERROR(AG16/AMAZON!J50,0) -> 0 | AI16: =TEMU!J42 -> 0 | AJ16: =IFERROR(AI16/TEMU!J25,0) -> 0 | AK16: =SHEIN!J33 -> 0 | AL16: =IFERROR(AK16/SHEIN!J20,0) -> 0 | AM16: =TK!J42 -> 0 | AN16: =IFERROR(AM16/TK!J25,0) -> 0 | AS16: =AG16+AI16+AK16+AM16+AO16+AQ16 -> 0 | AT16: =IFERROR(AS16/(AG11+AI11+AK11+AM11),0) -> 0 | AU16: =IFERROR((AS16-AD16)/AD16,0) -> 0 | AV16: =AMAZON!L87 -> 0 | AW16: =IFERROR(AV16/AMAZON!L50,0) -> 0 | AX16: =TEMU!L42 -> 0 | AY16: =IFERROR(AX16/TEMU!L25,0) -> 0 | AZ16: =SHEIN!L33 -> 0 | BA16: =IFERROR(AZ16/SHEIN!L20,0) -> 0 | BB16: =TK!L42 -> 0 | BC16: =IFERROR(BB16/TK!L25,0) -> 0 | BH16: =AV16+AX16+AZ16+BB16+BD16+BF16 -> 0 | BI16: =IFERROR(BH16/(AV11+AX11+AZ11+BB11),0) -> 0 | BJ16: =IFERROR((BH16-AS16)/AS16,0) -> 0 | BK16: =AMAZON!N87 -> 0 | BL16: =IFERROR(BK16/AMAZON!N50,0) -> 0 | BM16: =TEMU!N42 -> 0 | BN16: =IFERROR(BM16/TEMU!N25,0) -> 0 | BO16: =SHEIN!N33 -> 0 | BP16: =IFERROR(BO16/SHEIN!N20,0) -> 0 | BQ16: =TK!N42 -> 0 | BR16: =IFERROR(BQ16/TK!N25,0) -> 0 | BW16: =BK16+BM16+BO16+BQ16+BS16+BU16 -> 0 | BX16: =IFERROR(BW16/(BK11+BM11+BO11+BQ11),0) -> 0 | BY16: =IFERROR((BW16-BH16)/BH16,0) -> 0 | BZ16: =AMAZON!P87 -> 0 | CA16: =IFERROR(BZ16/AMAZON!P50,0) -> 0 | CB16: =TEMU!P42 -> 0 | CC16: =IFERROR(CB16/TEMU!P25,0) -> 0 | CD16: =SHEIN!P33 -> 0 | CE16: =IFERROR(CD16/SHEIN!P20,0) -> 0 | CF16: =TK!P42 -> 0 | CG16: =IFERROR(CF16/TK!P25,0) -> 0 | CL16: =BZ16+CB16+CD16+CF16+CH16+CJ16 -> 0 | CM16: =IFERROR(CL16/(BZ11+CB11+CD11+CF11),0) -> 0 | CN16: =IFERROR((CL16-BW16)/BW16,0) -> 0 | CO16: =AMAZON!R87 -> 0 | CP16: =IFERROR(CO16/AMAZON!R50,0) -> 0 | CQ16: =TEMU!R42 -> 0 | CR16: =IFERROR(CQ16/TEMU!R25,0) -> 0 | CS16: =SHEIN!R33 -> 0 | CT16: =IFERROR(CS16/SHEIN!R20,0) -> 0 | CU16: =TK!R42 -> 0 | CV16: =IFERROR(CU16/TK!R25,0) -> 0 | DA16: =CO16+CQ16+CS16+CU16+CW16+CY16 -> 0 | DB16: =IFERROR(DA16/(CO11+CQ11+CS11+CU11),0) -> 0 | DC16: =IFERROR((DA16-CL16)/CL16,0) -> 0 | DD16: =AMAZON!T87 -> 0 | DE16: =IFERROR(DD16/AMAZON!T50,0) -> 0 | DF16: =TEMU!T42 -> 0 | DG16: =IFERROR(DF16/TEMU!T25,0) -> 0 | DH16: =SHEIN!T33 -> 0 | DI16: =IFERROR(DH16/SHEIN!T20,0) -> 0 | DJ16: =TK!T42 -> 0 | DK16: =IFERROR(DJ16/TK!T25,0) -> 0 | DP16: =DD16+DF16+DH16+DJ16+DL16+DN16 -> 0 | DQ16: =IFERROR(DP16/(DD11+DF11+DH11+DJ11),0) -> 0 | DR16: =IFERROR((DP16-DA16)/DA16,0) -> 0 | DS16: =AMAZON!V87 -> 0 | DT16: =IFERROR(DS16/AMAZON!V50,0) -> 0 | DU16: =TEMU!V42 -> 0 | DV16: =IFERROR(DU16/TEMU!V25,0) -> 0 | DW16: =SHEIN!V33 -> 0 | DX16: =IFERROR(DW16/SHEIN!V20,0) -> 0 | DY16: =TK!V42 -> 0 | DZ16: =IFERROR(DY16/TK!V25,0) -> 0 | EE16: =DS16+DU16+DW16+DY16+EA16+EC16 -> 0 | EF16: =IFERROR(EE16/(DS11+DU11+DW11+DY11),0) -> 0 | EG16: =IFERROR((EE16-DP16)/DP16,0) -> 0 | EH16: =AMAZON!X87 -> 0 | EI16: =IFERROR(EH16/AMAZON!X50,0) -> 0 | EJ16: =TEMU!X42 -> 0 | EK16: =IFERROR(EJ16/TEMU!X25,0) -> 0 | EL16: =SHEIN!X33 -> 0 | EM16: =IFERROR(EL16/SHEIN!X20,0) -> 0 | EN16: =TK!X42 -> 0 | EO16: =IFERROR(EN16/TK!X25,0) -> 0 | ET16: =EH16+EJ16+EL16+EN16+EP16+ER16 -> 0 | EU16: =IFERROR(ET16/(EH11+EJ11+EL11+EN11),0) -> 0 | EV16: =IFERROR((ET16-EE16)/EE16,0) -> 0 | EW16: =AMAZON!Z87 -> 0 | EX16: =IFERROR(EW16/AMAZON!Z50,0) -> 0 | EY16: =TEMU!Z42 -> 0 | EZ16: =IFERROR(EY16/TEMU!Z25,0) -> 0 | FA16: =SHEIN!Z33 -> 0 | FB16: =IFERROR(FA16/SHEIN!Z20,0) -> 0 | FC16: =TK!Z42 -> 0 | FD16: =IFERROR(FC16/TK!Z25,0) -> 0 | FI16: =EW16+EY16+FA16+FC16+FE16+FG16 -> 0 | FJ16: =IFERROR(FI16/(EW11+EY11+FA11+FC11),0) -> 0 | FK16: =IFERROR((FI16-ET16)/ET16,0) -> 0 | FL16: =AMAZON!AB87 -> 0 | FM16: =IFERROR(FL16/AMAZON!AB50,0) -> 0 | FN16: =TEMU!AB42 -> 0 | FO16: =IFERROR(FN16/TEMU!AB25,0) -> 0 | FP16: =SHEIN!AB33 -> 0 | FQ16: =IFERROR(FP16/SHEIN!AB20,0) -> 0 | FR16: =TK!AB42 -> 0 | FS16: =IFERROR(FR16/TK!AB25,0) -> 0 | FX16: =FL16+FN16+FP16+FR16+FT16+FV16 -> 0 | FY16: =IFERROR(FX16/(FL11+FN11+FP11+FR11),0) -> 0 | FZ16: =IFERROR((FX16-FI16)/FI16,0) -> 0 | GA16: =AMAZON!AD87 -> 0 | GB16: =IFERROR(GA16/AMAZON!AD50,0) -> 0 | GC16: =TEMU!AD42 -> 0 | GD16: =IFERROR(GC16/TEMU!AD25,0) -> 0 | GE16: =SHEIN!AD33 -> 0 | GF16: =IFERROR(GE16/SHEIN!AD20,0) -> 0 | GG16: =TK!AD42 -> 0 | GH16: =IFERROR(GG16/TK!AD25,0) -> 0 | GM16: =GA16+GC16+GE16+GG16+GI16+GK16 -> 0 | GN16: =IFERROR(GM16/(GA11+GC11+GE11+GG11),0) -> 0 | GO16: =IFERROR((GM16-FX16)/FX16,0) -> 0
A17: 平台费用 | C17: 元 | D17: =AMAZON!F96 -> 0 | E17: =IFERROR(D17/AMAZON!F50,0) -> 0 | F17: =TEMU!F46 -> 0 | G17: =IFERROR(F17/TEMU!F25,0) -> 0 | H17: =SHEIN!F36 -> 0 | I17: =IFERROR(H17/SHEIN!F20,0) -> 0 | J17: =TK!F46 -> 0 | K17: =IFERROR(J17/TK!F25,0) -> 0 | P17: =D17+F17+H17+J17+L17+N17 -> 0 | Q17: =IFERROR(P17/(D11+F11+H11+J11),0) -> 0 | R17: =AMAZON!H96 -> 0 | S17: =IFERROR(R17/AMAZON!H50,0) -> 0 | T17: =TEMU!H46 -> 0 | U17: =IFERROR(T17/TEMU!H25,0) -> 0 | V17: =SHEIN!H36 -> 0 | W17: =IFERROR(V17/SHEIN!H20,0) -> 0 | X17: =TK!H46 -> 0 | Y17: =IFERROR(X17/TK!H25,0) -> 0 | AD17: =R17+T17+V17+X17+Z17+AB17 -> 0 | AE17: =IFERROR(AD17/(R11+T11+V11+X11),0) -> 0 | AG17: =AMAZON!J96 -> 0 | AH17: =IFERROR(AG17/AMAZON!J50,0) -> 0 | AI17: =TEMU!J46 -> 0 | AJ17: =IFERROR(AI17/TEMU!J25,0) -> 0 | AK17: =SHEIN!J36 -> 0 | AL17: =IFERROR(AK17/SHEIN!J20,0) -> 0 | AM17: =TK!J46 -> 0 | AN17: =IFERROR(AM17/TK!J25,0) -> 0 | AS17: =AG17+AI17+AK17+AM17+AO17+AQ17 -> 0 | AT17: =IFERROR(AS17/(AG11+AI11+AK11+AM11),0) -> 0 | AU17: =IFERROR((AS17-AD17)/AD17,0) -> 0 | AV17: =AMAZON!L96 -> 0 | AW17: =IFERROR(AV17/AMAZON!L50,0) -> 0 | AX17: =TEMU!L46 -> 0 | AY17: =IFERROR(AX17/TEMU!L25,0) -> 0 | AZ17: =SHEIN!L36 -> 0 | BA17: =IFERROR(AZ17/SHEIN!L20,0) -> 0 | BB17: =TK!L46 -> 0 | BC17: =IFERROR(BB17/TK!L25,0) -> 0 | BH17: =AV17+AX17+AZ17+BB17+BD17+BF17 -> 0 | BI17: =IFERROR(BH17/(AV11+AX11+AZ11+BB11),0) -> 0 | BJ17: =IFERROR((BH17-AS17)/AS17,0) -> 0 | BK17: =AMAZON!N96 -> 0 | BL17: =IFERROR(BK17/AMAZON!N50,0) -> 0 | BM17: =TEMU!N46 -> 0 | BN17: =IFERROR(BM17/TEMU!N25,0) -> 0 | BO17: =SHEIN!N36 -> 0 | BP17: =IFERROR(BO17/SHEIN!N20,0) -> 0 | BQ17: =TK!N46 -> 0 | BR17: =IFERROR(BQ17/TK!N25,0) -> 0 | BW17: =BK17+BM17+BO17+BQ17+BS17+BU17 -> 0 | BX17: =IFERROR(BW17/(BK11+BM11+BO11+BQ11),0) -> 0 | BY17: =IFERROR((BW17-BH17)/BH17,0) -> 0 | BZ17: =AMAZON!P96 -> 0 | CA17: =IFERROR(BZ17/AMAZON!P50,0) -> 0 | CB17: =TEMU!P46 -> 0 | CC17: =IFERROR(CB17/TEMU!P25,0) -> 0 | CD17: =SHEIN!P36 -> 0 | CE17: =IFERROR(CD17/SHEIN!P20,0) -> 0 | CF17: =TK!P46 -> 0 | CG17: =IFERROR(CF17/TK!P25,0) -> 0 | CL17: =BZ17+CB17+CD17+CF17+CH17+CJ17 -> 0 | CM17: =IFERROR(CL17/(BZ11+CB11+CD11+CF11),0) -> 0 | CN17: =IFERROR((CL17-BW17)/BW17,0) -> 0 | CO17: =AMAZON!R96 -> 0 | CP17: =IFERROR(CO17/AMAZON!R50,0) -> 0 | CQ17: =TEMU!R46 -> 0 | CR17: =IFERROR(CQ17/TEMU!R25,0) -> 0 | CS17: =SHEIN!R36 -> 0 | CT17: =IFERROR(CS17/SHEIN!R20,0) -> 0 | CU17: =TK!R46 -> 0 | CV17: =IFERROR(CU17/TK!R25,0) -> 0 | DA17: =CO17+CQ17+CS17+CU17+CW17+CY17 -> 0 | DB17: =IFERROR(DA17/(CO11+CQ11+CS11+CU11),0) -> 0 | DC17: =IFERROR((DA17-CL17)/CL17,0) -> 0 | DD17: =AMAZON!T96 -> 0 | DE17: =IFERROR(DD17/AMAZON!T50,0) -> 0 | DF17: =TEMU!T46 -> 0 | DG17: =IFERROR(DF17/TEMU!T25,0) -> 0 | DH17: =SHEIN!T36 -> 0 | DI17: =IFERROR(DH17/SHEIN!T20,0) -> 0 | DJ17: =TK!T46 -> 0 | DK17: =IFERROR(DJ17/TK!T25,0) -> 0 | DP17: =DD17+DF17+DH17+DJ17+DL17+DN17 -> 0 | DQ17: =IFERROR(DP17/(DD11+DF11+DH11+DJ11),0) -> 0 | DR17: =IFERROR((DP17-DA17)/DA17,0) -> 0 | DS17: =AMAZON!V96 -> 0 | DT17: =IFERROR(DS17/AMAZON!V50,0) -> 0 | DU17: =TEMU!V46 -> 0 | DV17: =IFERROR(DU17/TEMU!V25,0) -> 0 | DW17: =SHEIN!V36 -> 0 | DX17: =IFERROR(DW17/SHEIN!V20,0) -> 0 | DY17: =TK!V46 -> 0 | DZ17: =IFERROR(DY17/TK!V25,0) -> 0 | EE17: =DS17+DU17+DW17+DY17+EA17+EC17 -> 0 | EF17: =IFERROR(EE17/(DS11+DU11+DW11+DY11),0) -> 0 | EG17: =IFERROR((EE17-DP17)/DP17,0) -> 0 | EH17: =AMAZON!X96 -> 0 | EI17: =IFERROR(EH17/AMAZON!X50,0) -> 0 | EJ17: =TEMU!X46 -> 0 | EK17: =IFERROR(EJ17/TEMU!X25,0) -> 0 | EL17: =SHEIN!X36 -> 0 | EM17: =IFERROR(EL17/SHEIN!X20,0) -> 0 | EN17: =TK!X46 -> 0 | EO17: =IFERROR(EN17/TK!X25,0) -> 0 | ET17: =EH17+EJ17+EL17+EN17+EP17+ER17 -> 0 | EU17: =IFERROR(ET17/(EH11+EJ11+EL11+EN11),0) -> 0 | EV17: =IFERROR((ET17-EE17)/EE17,0) -> 0 | EW17: =AMAZON!Z96 -> 0 | EX17: =IFERROR(EW17/AMAZON!Z50,0) -> 0 | EY17: =TEMU!Z46 -> 0 | EZ17: =IFERROR(EY17/TEMU!Z25,0) -> 0 | FA17: =SHEIN!Z36 -> 0 | FB17: =IFERROR(FA17/SHEIN!Z20,0) -> 0 | FC17: =TK!Z46 -> 0 | FD17: =IFERROR(FC17/TK!Z25,0) -> 0 | FI17: =EW17+EY17+FA17+FC17+FE17+FG17 -> 0 | FJ17: =IFERROR(FI17/(EW11+EY11+FA11+FC11),0) -> 0 | FK17: =IFERROR((FI17-ET17)/ET17,0) -> 0 | FL17: =AMAZON!AB96 -> 0 | FM17: =IFERROR(FL17/AMAZON!AB50,0) -> 0 | FN17: =TEMU!AB46 -> 0 | FO17: =IFERROR(FN17/TEMU!AB25,0) -> 0 | FP17: =SHEIN!AB36 -> 0 | FQ17: =IFERROR(FP17/SHEIN!AB20,0) -> 0 | FR17: =TK!AB46 -> 0 | FS17: =IFERROR(FR17/TK!AB25,0) -> 0 | FX17: =FL17+FN17+FP17+FR17+FT17+FV17 -> 0 | FY17: =IFERROR(FX17/(FL11+FN11+FP11+FR11),0) -> 0 | FZ17: =IFERROR((FX17-FI17)/FI17,0) -> 0 | GA17: =AMAZON!AD96 -> 0 | GB17: =IFERROR(GA17/AMAZON!AD50,0) -> 0 | GC17: =TEMU!AD46 -> 0 | GD17: =IFERROR(GC17/TEMU!AD25,0) -> 0 | GE17: =SHEIN!AD36 -> 0 | GF17: =IFERROR(GE17/SHEIN!AD20,0) -> 0 | GG17: =TK!AD46 -> 0 | GH17: =IFERROR(GG17/TK!AD25,0) -> 0 | GM17: =GA17+GC17+GE17+GG17+GI17+GK17 -> 0 | GN17: =IFERROR(GM17/(GA11+GC11+GE11+GG11),0) -> 0 | GO17: =IFERROR((GM17-FX17)/FX17,0) -> 0
